Workbook
Name _: #N/A
Name _10_3__Crite: #REF!
Name _10A_: [1]연돌일위집계!#REF!
Name _10A_: [1]연돌일위집계!#REF!
Name _10A_: [1]연돌일위집계!#REF!
Name _10A_: [1]연돌일위집계!#REF!
Name _10A_: [1]연돌일위집계!#REF!
Name _10A_1: [1]연돌일위집계!#REF!
Name _10A_1: [1]연돌일위집계!#REF!
Name _10A_1: [1]연돌일위집계!#REF!
Name _10A_1: [1]연돌일위집계!#REF!
Name _10A_1: [1]연돌일위집계!#REF!
Name _10A_10: [1]연돌일위집계!#REF!
Name _10A_10: [1]연돌일위집계!#REF!
Name _10A_10: [1]연돌일위집계!#REF!
Name _10A_10: [1]연돌일위집계!#REF!
Name _10A_10: [1]연돌일위집계!#REF!
Name _10A_11: [1]연돌일위집계!#REF!
Name _10A_11: [1]연돌일위집계!#REF!
Name _10A_11: [1]연돌일위집계!#REF!
Name _10A_11: [1]연돌일위집계!#REF!
Name _10A_11: [1]연돌일위집계!#REF!
Name _10A_12: [1]연돌일위집계!#REF!
Name _10A_12: [1]연돌일위집계!#REF!
Name _10A_12: [1]연돌일위집계!#REF!
Name _10A_12: [1]연돌일위집계!#REF!
Name _10A_12: [1]연돌일위집계!#REF!
Name _10A_13: [1]연돌일위집계!#REF!
Name _10A_13: [1]연돌일위집계!#REF!
Name _10A_13: [1]연돌일위집계!#REF!
Name _10A_13: [1]연돌일위집계!#REF!
Name _10A_13: [1]연돌일위집계!#REF!
Name _10A_14: [1]연돌일위집계!#REF!
Name _10A_14: [1]연돌일위집계!#REF!
Name _10A_14: [1]연돌일위집계!#REF!
Name _10A_14: [1]연돌일위집계!#REF!
Name _10A_14: [1]연돌일위집계!#REF!
Name _10A_15: [1]연돌일위집계!#REF!
Name _10A_15: [1]연돌일위집계!#REF!
Name _10A_15: [1]연돌일위집계!#REF!
Name _10A_15: [1]연돌일위집계!#REF!
Name _10A_15: [1]연돌일위집계!#REF!
Name _10A_16: [1]연돌일위집계!#REF!
Name _10A_16: [1]연돌일위집계!#REF!
Name _10A_16: [1]연돌일위집계!#REF!
Name _10A_16: [1]연돌일위집계!#REF!
Name _10A_16: [1]연돌일위집계!#REF!
Name _10A_17: [1]연돌일위집계!#REF!
Name _10A_17: [1]연돌일위집계!#REF!
Name _10A_17: [1]연돌일위집계!#REF!
Name _10A_17: [1]연돌일위집계!#REF!
Name _10A_17: [1]연돌일위집계!#REF!
Name _10A_18: [1]연돌일위집계!#REF!
Name _10A_18: [1]연돌일위집계!#REF!
Name _10A_18: [1]연돌일위집계!#REF!
Name _10A_18: [1]연돌일위집계!#REF!
Name _10A_18: [1]연돌일위집계!#REF!
Name _10A_19: [1]연돌일위집계!#REF!
Name _10A_19: [1]연돌일위집계!#REF!
Name _10A_19: [1]연돌일위집계!#REF!

Sheet 공통
B2: 집행계획 (차수 구분~특기사항 사이 라인번호 순서대로, 중복 및 누락 없도록)
B3: 사업명 | J3: 공사코드 | L3: 발주처 | N3: 계약처 | R3: PJT명 - 코드 생성된 계약 명, 공사코드 - 해당 PJT 코드 번호
B4: 견적품의 | E4: 매출액 | G4: 재료비 | I4: 노무비 | K4: 외주비 | M4: 경비 | O4: 영업이익
B5: 집행계획 차수 | E5: 0 | F5: 계약 방법 | H5: 수금 조건 | J5: 고객 담당자 | L5: 고객 연락처 | N5: 영업 담당자 | O5: 정성원 | R5: 발주처 - 해당 PJT의 의뢰처, 계약처 - 해당 PJT의 계약처 (발주처와 계약처 다를 수 있음)
B6: 년도 구분 | E6: 2025년 | G6: 2026년
B7: 집행 구분 | E7: 최초 | F7: 수정 | G7: 이월
B8: 차수 구분 | D8: 1 | E8: 0 | F8: 1 | G8: 2 | H8: 3 | I8: 4 | J8: 5 | K8: 6 | L8: 7 | M8: 8 | N8: 9 | O8: 10 | P8: 11 | R8: 본 집행시 반드시 '0'차로 표시, 1차수부터는 수정 집행임
B9: 견적서 작성일 | D9: 2 | R9: 영업 견적서 작성일
B10: 집행계획 작성일 | D10: 3 | R10: 집행 계획 작성일
B11: 낙찰율 | D11: 4 | R11: 낙찰율 변경 시 요율 변경 (고객사 제출한 견적 대비 실제 계약 금액 비교)
B12: 현장소장 (PM) | D12: 5 | R12: PM 변경 시 이름 변경
B13: 정산누계(~전년도) | D13: 6 | R13: 집행예산집계표 기준
B14: 당기계획(올해) | D14: 7 | R14: 집행예산집계표 기준
B15: 당기이후(내년) | D15: 8 | R15: 집행예산집계표 기준
B16: 당기이후(내후년~) | D16: 9 | R16: 집행예산집계표 기준
B17: 간접비 요율 | D17: 10 | R17: 집행예산집계표 기준 (요율은 윤지민과장에게 문의)
B18: 일반관리비 요율 | D18: 11 | R18: 집행예산집계표 기준 (요율은 윤지민과장에게 문의)
B19: 국민연금 요율 | D19: 12 | R19: 집행예산산출내역서 기준
B20: 건강보험 요율 | D20: 13 | R20: 집행예산산출내역서 기준
... B22: 고용보험 요율 | D22: 15 | R22: 집행예산산출내역서 기준
B23: 급료 (직원) | C23: 산출내역 | D23: 16 | R23: 집행예산산출내역서 기준 - 부장 7,500,000원, 차장 6,500,000원, 과장 5,500,000원, 대리 4,500,000원, 사원 3,500,000원
C24: 계약금액 | D24: 17 | R24: 집행예산산출내역서 기준
C25: 집행계획 | D25: 18 | R25: 집행예산산출내역서 기준
C26: 정산누계(~2025년) | D26: 19 | R26: 집행예산산출내역서 기준
C27: 당기계획(2026년) | D27: 20 | R27: 집행예산산출내역서 기준
C28: 당기이후(2027년) | D28: 21 | R28: 집행예산산출내역서 기준
C29: 당기이후(2028년~) | D29: 22 | R29: 집행예산산출내역서 기준
B30: 상여금 (직원) | C30: 산출내역 | D30: 23 | R30: 집행예산산출내역서 기준 - 상여가 지급된 달의 전 달 급여 코드에 반영 (ex. 상여가 1월 25일에 지급 됐다면 12월 급여 코드에 상여금 반영, 1M/M 급여로 책정) - 추석상여 (ex. 투입기간 3월~8월이고, 추석이 9월이면 6/9 책정), 설 상여 (1월 혹은 2월 투입 시 책정)
C31: 집행계획 | D31: 24 | R31: 집행예산산출내역서 기준
C32: 정산누계(~2025년) | D32: 25 | R32: 집행예산산출내역서 기준
C33: 당기계획(2026년) | D33: 26 | R33: 집행예산산출내역서 기준
C34: 당기이후(2027년) | D34: 27 | R34: 집행예산산출내역서 기준
C35: 당기이후(2028년~) | D35: 28 | R35: 집행예산산출내역서 기준
B36: 임금 (현장사원) | C36: 산출내역 | D36: 29 | R36: 집행예산산출내역서 기준 - 실급여 기준, 현장사원과 장기 계약이 예정되어 있는 경우 임금 상승분 고려해야 함
C37: 계약금액 | D37: 30 | R37: 집행예산산출내역서 기준
C38: 집행계획 | D38: 31 | R38: 집행예산산출내역서 기준
C39: 정산누계(~2025년) | D39: 32 | R39: 집행예산산출내역서 기준
C40: 당기계획(2026년) | D40: 33 | R40: 집행예산산출내역서 기준
C41: 당기이후(2027년) | D41: 34 | R41: 집행예산산출내역서 기준
C42: 당기이후(2028년~) | D42: 35 | R42: 집행예산산출내역서 기준
...

Sheet 0. 집행계획(갑지)
AH3: 지원팀장 : 가급적 영업지원팀장에게 결재, 부재 시 그 외 지원팀장에게 결재
E4: [ □ 가 ■ 본 ] | H4: 집 행 계 획 서
D7: ="1.공 사 명 : " & 공통!E3 & " (공사코드: " & 공통!K3 & ")" -> 1.공 사 명 : (공사코드: )
D8: ="2.공사기간 : " & 공통!E127 & " (" & 공통!E128 & " 일간)" -> 2.공사기간 : ( 일간)
D9: ="3.현장소장 : " & 공통!E12 & " (서명)" -> 3.현장소장 : (서명) | W9: ="작성일자 : "&TEXT(공통!E10,"yyyy-mm-dd") -> 작성일자 : 1900-01-00
D10: 4.예산집행계획 | X10: [단위:천원,%]
D11: 구 분 | F11: 수주손익 | H11: 계약금액 | J11: 집행계획(A) | L11: 정산누계(B) [~25년] | N11: 당기 계획 (C) | P11: 당기 이후 | W11: 총계(E=B+C+D)
N12: [26년] | P12: [27년] | R12: [28년~] | T12: 소계 [D]
F13: 금 액 | G13: % | H13: 금 액 | I13: % | J13: 금 액 | K13: % | L13: 금 액 | M13: % | N13: 금 액 | O13: % | P13: 금 액 | Q13: % | R13: 금 액 | S13: % | T13: 금 액 | V13: % | W13: 금 액 | X13: %
D14: 매 출 액 | F14: =공통!F4 -> 0 | G14: =IFERROR((F14/F14*100),0) | H14: ='4. 집행예산집계표'!F9 -> 0 | I14: ='4. 집행예산집계표'!G9 -> 0 | J14: ='4. 집행예산집계표'!H9 -> 0 | K14: ='4. 집행예산집계표'!I9 -> 0 | L14: ='4. 집행예산집계표'!J9 -> 0 | M14: =IFERROR(($L14/$J14*100),0) -> 0 | N14: ='4. 집행예산집계표'!L9 -> 0 | O14: =IFERROR((N$14/$J14*100),0) -> 0 | P14: ='4. 집행예산집계표'!N9 -> 0 | Q14: =IFERROR((P$14/$J14*100),0) -> 0 | R14: ='4. 집행예산집계표'!P9 -> 0 | S14: =IFERROR((R$14/$J14*100),0) -> 0 | T14: =P14+R14 -> 0 | V14: =IFERROR((T$14/$J14*100),0) -> 0 | W14: =L14+N14+T14 -> 0 | X14: =IFERROR((W$14/$J14*100),0) -> 0
D15: 재 료 비 | F15: =공통!H4 -> 0 | G15: =IFERROR((F$15/F$14*100),0) -> 0 | H15: ='4. 집행예산집계표'!F10 -> 0 | I15: =IFERROR((H$15/H$14*100),0) -> 0 | J15: ='4. 집행예산집계표'!H10 -> 0 | K15: =IFERROR((J15/J$14*100),0) -> 0 | L15: ='4. 집행예산집계표'!J10 -> 0 | M15: =IFERROR((L15/L$14*100),0) -> 0 | N15: ='4. 집행예산집계표'!L10 -> 0 | O15: =IFERROR((N15/N$14*100),0) -> 0 | P15: ='4. 집행예산집계표'!N10 -> 0 | Q15: =IFERROR((P15/P$14*100),0) -> 0 | R15: ='4. 집행예산집계표'!P10 -> 0 | S15: =IFERROR((R15/R$14*100),0) -> 0 | T15: =P15+R15 -> 0 | V15: =IFERROR((T15/T$14*100),0) -> 0 | W15: =L15+N15+T15 -> 0 | X15: =IFERROR(W$15/W$14*100,0)
D16: 노 무 비 | F16: =공통!J4 -> 0 | G16: =IFERROR((F$16/F$14*100),0) -> 0 | H16: ='4. 집행예산집계표'!F13 -> 0 | I16: =IFERROR((H$16/H$14*100),0) -> 0 | J16: ='4. 집행예산집계표'!H13 -> 0 | K16: =IFERROR((J16/J$14*100),0) -> 0 | L16: ='4. 집행예산집계표'!J13 -> 0 | M16: =IFERROR((L16/L$14*100),0) -> 0 | N16: ='4. 집행예산집계표'!L13 -> 0 | O16: =IFERROR((N16/N$14*100),0) -> 0 | P16: ='4. 집행예산집계표'!N13 -> 0 | Q16: =IFERROR((P16/P$14*100),0) -> 0 | R16: ='4. 집행예산집계표'!P13 -> 0 | S16: =IFERROR((R16/R$14*100),0) -> 0 | T16: =P16+R16 -> 0 | V16: =IFERROR((T16/T$14*100),0) -> 0 | W16: =L16+N16+T16 -> 0 | X16: =IFERROR(W$16/W$14*100,0)
D17: 외 주 비 | F17: =공통!L4 -> 0 | G17: =IFERROR((F$17/F$14*100),0) -> 0 | H17: ='4. 집행예산집계표'!F19 -> 0 | I17: =IFERROR((H$17/H$14*100),0) -> 0 | J17: ='4. 집행예산집계표'!H19 -> 0 | K17: =IFERROR((J17/J$14*100),0) -> 0 | L17: ='4. 집행예산집계표'!J19 -> 0 | M17: =IFERROR((L17/L$14*100),0) -> 0 | N17: ='4. 집행예산집계표'!L19 -> 0 | O17: =IFERROR((N17/N$14*100),0) -> 0 | P17: ='4. 집행예산집계표'!N19 -> 0 | Q17: =IFERROR((P17/P$14*100),0) -> 0 | R17: ='4. 집행예산집계표'!P19 -> 0 | S17: =IFERROR((R17/R$14*100),0) -> 0 | T17: =P17+R17 -> 0 | V17: =IFERROR((T17/T$14*100),0) -> 0 | W17: =L17+N17+T17 -> 0 | X17: =IFERROR(W$17/W$14*100,0)
D18: 경 비 | F18: =공통!N4 | G18: =IFERROR((F$18/F$14*100),0) -> 0 | H18: ='4. 집행예산집계표'!F22 -> 0 | I18: =IFERROR((H$18/H$14*100),0) -> 0 | J18: ='4. 집행예산집계표'!H22 -> 0 | K18: =IFERROR((J18/J$14*100),0) -> 0 | L18: ='4. 집행예산집계표'!J22 -> 0 | M18: =IFERROR((L18/L$14*100),0) -> 0 | N18: ='4. 집행예산집계표'!L22 -> 0 | O18: =IFERROR((N18/N$14*100),0) -> 0 | P18: ='4. 집행예산집계표'!N22 -> 0 | Q18: =IFERROR((P18/P$14*100),0) -> 0 | R18: ='4. 집행예산집계표'!P22 -> 0 | S18: =IFERROR((R18/R$14*100),0) -> 0 | T18: =P18+R18 -> 0 | V18: =IFERROR((T18/T$14*100),0) -> 0 | W18: =L18+N18+T18 -> 0 | X18: =IFERROR(W$18/W$14*100,0)
D19: 합 계 | F19: =SUM(F15:F18) -> 0 | G19: =IFERROR((F19/F14*100),0) -> 0 | H19: =SUM(H15:H18) -> 0 | I19: =IFERROR((H19/H14*100),0) -> 0 | J19: =SUM(J15:J18) -> 0 | K19: =IFERROR((J19/J$14*100),0) -> 0 | L19: =SUM(L15:L18) -> 0 | M19: =IFERROR((L19/L$14*100),0) -> 0 | N19: =SUM(N15:N18) -> 0 | O19: =IFERROR((N19/N$14*100),0) -> 0 | P19: =SUM(P15:P18) -> 0 | Q19: =IFERROR((P19/P$14*100),0) -> 0 | R19: =SUM(R15:R18) -> 0 | S19: =IFERROR((R19/R$14*100),0) -> 0 | T19: =SUM(T15:U18) -> 0 | V19: =IFERROR((T19/T$14*100),0) -> 0 | W19: =SUM(W15:W18) -> 0 | X19: =IFERROR(W19/W14*100,0)
D20: 영업이익 | F20: =공통!P4 | G20: =IFERROR((F20/F14*100),0) -> 0 | J20: ='4. 집행예산집계표'!H42 -> 0 | K20: =IFERROR((J20/J$14*100),0) -> 0 | L20: ='4. 집행예산집계표'!J42 -> 0 | M20: =IFERROR((L20/L$14*100),0) -> 0 | N20: ='4. 집행예산집계표'!L42 -> 0 | O20: =IFERROR((N20/N$14*100),0) -> 0 | P20: ='4. 집행예산집계표'!N42 -> 0 | Q20: =IFERROR((P20/P$14*100),0) -> 0 | R20: ='4. 집행예산집계표'!P42 -> 0 | S20: =IFERROR((R20/R$14*100),0) -> 0 | T20: ='4. 집행예산집계표'!R42 -> 0 | V20: =IFERROR((T20/T$14*100),0) -> 0 | W20: ='4. 집행예산집계표'!T42 -> 0 | X20: =IFERROR(W20/W14*100,0)
D21: 5. 특기사항
D22: 1) 계약관계
D23: =" ① 발주처 : " & 공통!M3 -> ① 발주처 : | Q23: 조 건 | S23: 보증요율 | V23: 보증 금액[VAT별도]
D24: =" ② 계약처 : " & 공통!O3 -> ② 계약처 : | Q24: 선 급 금 | S24: ■ 무 □ 유( %) | V24: 천원 | AA24: 계약서 명시 내용 작성
D25: =" ③ 계약방식 : " & 공통!G5 -> ③ 계약방식 : | Q25: 계약이행 | S25: ■ 무 □ 유( %) | V25: 천원 | AA25: 계약서 명시 내용 작성
D26: =" ④ 기성, 수금 : " & 공통!I5 -> ④ 기성, 수금 : | Q26: 하자보수 | S26: ■ 무 □ 유( %) | V26: 천원 | AA26: 계약서 명시 내용 작성
D27: 2) 공사범위 | S27: ( 준 공 ) 후 ( )개월 | AA27: 계약서 명시 내용 작성
D28: =" ① " & 공통!E129 -> ① | Q28: 수 금 | S28: ■현금(30일) □어음(00일) □현금( %)+어음( %) | AA28: 현금/어음/현금+어음 혼합 각각 확인
D29: 3) 특수 계약조건 / 이슈내용 / 기타
Q30: 원가산출 기준 등
Q31: 계약물량 | S31: ■ 확정 □ 기타( ) | AA31: 계약 물량은 확정만 사용
S32: □ 부분실행 [ 물량확정 ( )월 후 예상 ]
Q33: 집행물량 | S33: ■ 계약 □ 도면검토 후 산출 | AA33: 집행 물량은 계약만 사용
Q34: 자재단가 | S34: □ 구매 ■ 최종 NEGO가 적용 | AA34: H/W가 있으면 구매, 없으면 견적 100%
Q35: 인 건 비 | S35: □ 정부품셈 대비 (35%+할증 30% 적용) ■ 기타 | AA35: 인건비는 무조건 기타만 사용
Q37: 구분 | S37: 절감액(0월말 기준) | V37: % | W37: 반영여부
Q38: 구매절감 | W38: 미반영
Q39: 외주절감 | W39: 미반영
Q40: 계
D42: ■ 첨 부 : 1.현장조직/업무분장 2.공사개요 3.예정공정표 4.집행예산집계표 5.집행예산 산출내역서(재료, 인력, 소모품) 6.동원계획(장비, 지급임차료, 인원 )
D44: GS네오텍 Page : | W44: GP-4050-01(1)

Sheet 4. 집행예산집계표
C2: 공사집행예산 집계표
C5: ='0. 집행계획(갑지)'!D7 -> 1.공 사 명 : (공사코드: ) | V5: 【 단위 : % , 천원 】
C6: 계 약 사 항 | E6: 구분 항목 | F6: 계약금액 | H6: 집 행 계 획(A) | J6: 정산누계(B) [~25년] | L6: 당기 계획 (C) | N6: 당기이후 | T6: 총계(E=B+C+D) | V6: 비고
L7: [26년] | N7: [27년] | P7: [28년~] | R7: 소계 (D)
F8: 금액 | G8: % | H8: 금액 | I8: % | J8: 금액 | K8: % | L8: 금액 | M8: % | N8: 금액 | O8: % | P8: 금액 | Q8: % | R8: 금액 | S8: % | T8: 금액 | U8: %
E9: 매출액 | F9: =F10+F13+F22 -> 0 | H9: =F9 -> 0 | I9: =G9 -> 0 | J9: =IFERROR((H9*공통!E13),0) -> 0 | K9: =IFERROR((J9/H9*100),0) -> 0 | L9: =IFERROR((H9*공통!E14),0) -> 0 | M9: =IFERROR((L9/H9*100),0) -> 0 | N9: =IFERROR((H9*공통!E15),0) -> 0 | O9: =IFERROR((N9/H9*100),0) -> 0 | P9: =IFERROR((H9*공통!E16),0) -> 0 | Q9: =IFERROR((P9/H9*100),0) -> 0 | R9: =N9+P9 -> 0 | S9: =IFERROR((R9/H9*100),0) -> 0 | T9: =J9+L9+R9 -> 0 | U9: =IFERROR((T9/H9*100),0) -> 0 | Y9: 25년도 3개월 25%, 26년도 9개월 75% (2025년 9월 15일~2026년 9월 14일)
C10: =" 1. 발 주 자 : "&공통!M3 -> 1. 발 주 자 : | E10: 재료비 | F10: =F11+F12 -> 0 | G10: =IFERROR((F10/F9*100),0) -> 0 | H10: =H11+H12 -> 0 | I10: =IFERROR((H10/H9*100),0) -> 0 | J10: =J11+J12 -> 0 | K10: =IFERROR((J10/J9*100),0) -> 0 | L10: =L11+L12 -> 0 | M10: =IFERROR((L10/L9*100),0) -> 0 | N10: =N11+N12 -> 0 | O10: =IFERROR((N10/N9*100),0) -> 0 | P10: =P11+P12 -> 0 | Q10: =IFERROR((P10/P9*100),0) -> 0 | R10: =N10+P10 -> 0 | S10: =IFERROR((R10/R9*100),0) -> 0 | T10: =J10+L10+R10 -> 0 | U10: =IFERROR((T10/T9*100),0) -> 0
E11: 본사재료비 | F11: ='5.집행예산산출내역서'!F8/1000 -> 0 | G11: =IFERROR((F11/F9*100),0) -> 0 | H11: ='5.집행예산산출내역서'!G8/1000 -> 0 | I11: =IFERROR((H11/H9*100),0) -> 0 | J11: ='5.집행예산산출내역서'!H8/1000 -> 0 | K11: =IFERROR((J11/J9*100),0) -> 0 | L11: ='5.집행예산산출내역서'!I8/1000 -> 0 | M11: =IFERROR((L11/L9*100),0) -> 0 | N11: ='5.집행예산산출내역서'!J8/1000 -> 0 | O11: =IFERROR((N11/N9*100),0) -> 0 | P11: ='5.집행예산산출내역서'!K8/1000 -> 0 | Q11: =IFERROR((P11/P9*100),0) -> 0 | R11: =N11+P11 -> 0 | S11: =IFERROR((R11/R9*100),0) -> 0 | T11: =J11+L11+R11 -> 0 | U11: =IFERROR((T11/T9*100),0) -> 0
C12: =" 2. 계약방법 : " & 공통!G5 -> 2. 계약방법 : | E12: 현지재료비 | F12: ='5.집행예산산출내역서'!F9/1000 -> 0 | G12: =IFERROR((F12/F9*100),0) -> 0 | H12: ='5.집행예산산출내역서'!G9/1000 -> 0 | I12: =IFERROR((H12/H9*100),0) -> 0 | J12: ='5.집행예산산출내역서'!H9/1000 -> 0 | K12: =IFERROR((J12/J9*100),0) -> 0 | L12: ='5.집행예산산출내역서'!I9/1000 -> 0 | M12: =IFERROR((L12/L9*100),0) -> 0 | N12: ='5.집행예산산출내역서'!J9/1000 -> 0 | O12: =IFERROR((N12/N9*100),0) -> 0 | P12: ='5.집행예산산출내역서'!K9/1000 -> 0 | Q12: =IFERROR((P12/P9*100),0) -> 0 | R12: =N12+P12 -> 0 | S12: =IFERROR((R12/R9*100),0) -> 0 | T12: =J12+L12+R12 -> 0 | U12: =IFERROR((T12/T9*100),0) -> 0
E13: 노무비 | F13: =SUM(F14:F18) -> 0 | G13: =IFERROR((F13/F9*100),0) -> 0 | H13: =SUM(H14:H18) -> 0 | I13: =IFERROR((H13/H9*100),0) -> 0 | J13: =SUM(J14:J18) -> 0 | K13: =IFERROR((J13/J9*100),0) -> 0 | L13: =SUM(L14:L18) -> 0 | M13: =IFERROR((L13/L9*100),0) -> 0 | N13: =SUM(N14:N18) -> 0 | O13: =IFERROR((N13/N9*100),0) -> 0 | P13: =SUM(P14:P18) -> 0 | Q13: =IFERROR((P13/P9*100),0) -> 0 | R13: =N13+P13 -> 0 | S13: =IFERROR((R13/R9*100),0) -> 0 | T13: =J13+L13+R13 -> 0 | U13: =IFERROR((T13/T9*100),0) -> 0
C14: =" 3. 낙 찰 율 : " & TEXT(공통!E11, "0%") -> 3. 낙 찰 율 : 0% | E14: 급료(직원) | F14: ='5.집행예산산출내역서'!F11/1000 -> 0 | G14: =IFERROR((F14/F9*100),0) -> 0 | H14: ='5.집행예산산출내역서'!G11/1000 -> 0 | I14: =IFERROR((H14/H9*100),0) -> 0 | J14: ='5.집행예산산출내역서'!H11/1000 -> 0 | K14: =IFERROR((J14/J9*100),0) -> 0 | L14: ='5.집행예산산출내역서'!I11/1000 -> 0 | M14: =IFERROR((L14/L9*100),0) -> 0 | N14: ='5.집행예산산출내역서'!J11/1000 -> 0 | O14: =IFERROR((N14/N9*100),0) -> 0 | P14: ='5.집행예산산출내역서'!K11/1000 -> 0 | Q14: =IFERROR((P14/P9*100),0) -> 0 | R14: =N14+P14 -> 0 | S14: =IFERROR((R14/R9*100),0) -> 0 | T14: =J14+L14+R14 -> 0 | U14: =IFERROR((T14/T9*100),0) -> 0
E15: 임금(현장) | F15: ='5.집행예산산출내역서'!F13/1000 -> 0 | G15: =IFERROR((F15/F9*100),0) -> 0 | H15: ='5.집행예산산출내역서'!G13/1000 -> 0 | I15: =IFERROR((H15/H9*100),0) -> 0 | J15: ='5.집행예산산출내역서'!H13/1000 -> 0 | K15: =IFERROR((J15/J9*100),0) -> 0 | L15: ='5.집행예산산출내역서'!I13/1000 -> 0 | M15: =IFERROR((L15/L9*100),0) -> 0 | N15: ='5.집행예산산출내역서'!J13/1000 -> 0 | O15: =IFERROR((N15/N9*100),0) -> 0 | P15: ='5.집행예산산출내역서'!K13/1000 -> 0 | Q15: =IFERROR((P15/P9*100),0) -> 0 | R15: =N15+P15 -> 0 | S15: =IFERROR((R15/R9*100),0) -> 0 | T15: =J15+L15+R15 -> 0 | U15: =IFERROR((T15/T9*100),0) -> 0
C16: 4. 공사기간 : | E16: 상여금(직원) | F16: ='5.집행예산산출내역서'!F15/1000 -> 0 | G16: =IFERROR((F16/F9*100),0) -> 0 | H16: ='5.집행예산산출내역서'!G15/1000 -> 0 | I16: =IFERROR((H16/H9*100),0) -> 0 | J16: ='5.집행예산산출내역서'!H15/1000 -> 0 | K16: =IFERROR((J16/J9*100),0) -> 0 | L16: ='5.집행예산산출내역서'!I15/1000 -> 0 | M16: =IFERROR((L16/L9*100),0) -> 0 | N16: ='5.집행예산산출내역서'!J15/1000 -> 0 | O16: =IFERROR((N16/N9*100),0) -> 0 | P16: ='5.집행예산산출내역서'!K15/1000 -> 0 | Q16: =IFERROR((P16/P9*100),0) -> 0 | R16: =N16+P16 -> 0 | S16: =IFERROR((R16/R9*100),0) -> 0 | T16: =J16+L16+R16 -> 0 | U16: =IFERROR((T16/T9*100),0) -> 0
C17: =" " & 공통!E127 | E17: 퇴직금(직원) | F17: ='5.집행예산산출내역서'!F17/1000 -> 0 | G17: =IFERROR((F17/F9*100),0) -> 0 | H17: ='5.집행예산산출내역서'!G17/1000 -> 0 | I17: =IFERROR((H17/H9*100),0) -> 0 | J17: ='5.집행예산산출내역서'!H17/1000 -> 0 | K17: =IFERROR((J17/J9*100),0) -> 0 | L17: ='5.집행예산산출내역서'!I17/1000 -> 0 | M17: =IFERROR((L17/L9*100),0) -> 0 | N17: ='5.집행예산산출내역서'!J17/1000 -> 0 | O17: =IFERROR((N17/N9*100),0) -> 0 | P17: ='5.집행예산산출내역서'!K17/1000 -> 0 | Q17: =IFERROR((P17/P9*100),0) -> 0 | R17: =N17+P17 -> 0 | S17: =IFERROR((R17/R9*100),0) -> 0 | T17: =J17+L17+R17 -> 0 | U17: =IFERROR((T17/T9*100),0) -> 0
E18: 퇴직금(현장) | F18: ='5.집행예산산출내역서'!F19/1000 -> 0 | G18: =IFERROR((F18/F9*100),0) -> 0 | H18: ='5.집행예산산출내역서'!G19/1000 -> 0 | I18: =IFERROR((H18/H9*100),0) -> 0 | J18: ='5.집행예산산출내역서'!H19/1000 -> 0 | K18: =IFERROR((J18/J9*100),0) -> 0 | L18: ='5.집행예산산출내역서'!I19/1000 -> 0 | M18: =IFERROR((L18/L9*100),0) -> 0 | N18: ='5.집행예산산출내역서'!J19/1000 -> 0 | O18: =IFERROR((N18/N9*100),0) -> 0 | P18: ='5.집행예산산출내역서'!K19/1000 -> 0 | Q18: =IFERROR((P18/P9*100),0) -> 0 | R18: =N18+P18 -> 0 | S18: =IFERROR((R18/R9*100),0) -> 0 | T18: =J18+L18+R18 -> 0 | U18: =IFERROR((T18/T9*100),0) -> 0
C19: =" 5. 계약 금액 : " & TEXT(F9, "#,##0") & " 천원" -> 5. 계약 금액 : 0 천원 | E19: 외주비 | F19: =SUM(F20:F21) -> 0 | G19: =IFERROR((F19/F9*100),0) -> 0 | H19: =SUM(H20:H21) -> 0 | I19: =IFERROR((H19/H9*100),0) -> 0 | J19: =SUM(J20:J21) -> 0 | K19: =IFERROR((J19/J9*100),0) -> 0 | L19: =SUM(L20:L21) -> 0 | M19: =IFERROR((L19/L9*100),0) -> 0 | N19: =SUM(N20:N21) -> 0 | O19: =IFERROR((N19/N9*100),0) -> 0 | P19: =SUM(P20:P21) -> 0 | Q19: =IFERROR((P19/P9*100),0) -> 0 | R19: =N19+P19 -> 0 | S19: =IFERROR((R19/R9*100),0) -> 0 | T19: =J19+L19+R19 -> 0 | U19: =IFERROR((T19/T9*100),0) -> 0
C20: =" 재 료 비 : " & TEXT(F10, "#,##0") & " 천원" -> 재 료 비 : 0 천원 | E20: 외주용역비 | F20: ='5.집행예산산출내역서'!F22 -> 0 | G20: =IFERROR((F20/F9*100),0) -> 0 | H20: ='5.집행예산산출내역서'!G22 -> 0 | I20: =IFERROR((H20/H9*100),0) -> 0 | J20: ='5.집행예산산출내역서'!H22 -> 0 | K20: =IFERROR((J20/J9*100),0) -> 0 | L20: ='5.집행예산산출내역서'!I22 -> 0 | M20: =IFERROR((L20/L9*100),0) -> 0 | N20: ='5.집행예산산출내역서'!J22 -> 0 | O20: =IFERROR((N20/N9*100),0) -> 0 | P20: ='5.집행예산산출내역서'!K22 -> 0 | Q20: =IFERROR((P20/P9*100),0) -> 0 | R20: ='5.집행예산산출내역서'!L22 -> 0 | S20: =IFERROR((R20/R9*100),0) -> 0 | T20: =J20+L20+R20 -> 0 | U20: =IFERROR((T20/T9*100),0) -> 0 | W20: =U20+S20 -> 0
C21: =" 노 무 비 : " & TEXT(F13, "#,##0") & " 천원" -> 노 무 비 : 0 천원 | E21: 외주가공비 | F21: ='5.집행예산산출내역서'!F23 -> 0 | G21: =IFERROR((F21/F9*100),0) -> 0 | H21: ='5.집행예산산출내역서'!G23 -> 0 | I21: =IFERROR((H21/H9*100),0) -> 0 | J21: ='5.집행예산산출내역서'!H23 -> 0 | K21: =IFERROR((J21/J9*100),0) -> 0 | L21: ='5.집행예산산출내역서'!I23 -> 0 | M21: =IFERROR((L21/L9*100),0) -> 0 | N21: ='5.집행예산산출내역서'!J23 -> 0 | O21: =IFERROR((N21/N9*100),0) -> 0 | P21: ='5.집행예산산출내역서'!K23 -> 0 | Q21: =IFERROR((P21/P9*100),0) -> 0 | R21: ='5.집행예산산출내역서'!L23 -> 0 | S21: =IFERROR((R21/R9*100),0) -> 0 | T21: =J21+L21+R21 -> 0 | U21: =IFERROR((T21/T9*100),0) -> 0 | W21: =U21+S21 -> 0
C22: =" 외 주 비 : " & TEXT(F19, "#,##0") & " 천원" -> 외 주 비 : 0 천원 | E22: 경 비 | F22: =SUM(F23:F37) -> 0 | G22: =IFERROR((F22/F9*100),0) -> 0 | H22: =SUM(H23:H37) -> 0 | I22: =IFERROR((H22/H9*100),0) -> 0 | J22: =SUM(J23:J37) -> 0 | K22: =IFERROR((J22/J9*100),0) -> 0 | L22: =SUM(L23:L37) -> 0 | M22: =IFERROR((L22/L9*100),0) -> 0 | N22: =SUM(N23:N37) -> 0 | O22: =IFERROR((N22/N9*100),0) -> 0 | P22: =SUM(P23:P37) -> 0 | Q22: =IFERROR((P22/P9*100),0) -> 0 | R22: =N22+P22 -> 0 | S22: =IFERROR((R22/R9*100),0) -> 0 | T22: =J22+L22+R22 -> 0 | U22: =IFERROR((T22/T9*100),0) -> 0
C23: =" 경 비 : " & TEXT(F22, "#,##0") & " 천원" -> 경 비 : 0 천원 | E23: 복리후생비 | F23: ='5.집행예산산출내역서'!F25/1000 -> 0 | G23: =IFERROR((F23/F9*100),0) -> 0 | H23: ='5.집행예산산출내역서'!G25/1000 -> 0 | I23: =IFERROR((H23/H9*100),0) -> 0 | J23: ='5.집행예산산출내역서'!H25/1000 -> 0 | K23: =IFERROR((J23/J9*100),0) -> 0 | L23: ='5.집행예산산출내역서'!I25/1000 -> 0 | M23: =IFERROR((L23/L9*100),0) -> 0 | N23: ='5.집행예산산출내역서'!J25/1000 -> 0 | O23: =IFERROR((N23/N9*100),0) -> 0 | P23: ='5.집행예산산출내역서'!K25/1000 -> 0 | Q23: =IFERROR((P23/P9*100),0) -> 0 | R23: =N23+P23 -> 0 | S23: =IFERROR((R23/R9*100),0) -> 0 | T23: =J23+L23+R23 -> 0 | U23: =IFERROR((T23/T9*100),0) -> 0
E24: 보험료 | F24: ='5.집행예산산출내역서'!F26/1000 -> 0 | G24: =IFERROR((F24/F9*100),0) -> 0 | H24: ='5.집행예산산출내역서'!G26/1000 -> 0 | I24: =IFERROR((H24/H9*100),0) -> 0 | J24: ='5.집행예산산출내역서'!H26/1000 -> 0 | K24: =IFERROR((J24/J9*100),0) -> 0 | L24: ='5.집행예산산출내역서'!I26/1000 -> 0 | M24: =IFERROR((L24/L9*100),0) -> 0 | N24: ='5.집행예산산출내역서'!J26/1000 -> 0 | O24: =IFERROR((N24/N9*100),0) -> 0 | P24: ='5.집행예산산출내역서'!K26/1000 -> 0 | Q24: =IFERROR((P24/P9*100),0) -> 0 | R24: =N24+P24 -> 0 | S24: =IFERROR((R24/R9*100),0) -> 0 | T24: =J24+L24+R24 -> 0 | U24: =IFERROR((T24/T9*100),0) -> 0 | V24: 보험료 정산조건
C25: =" 6. 현장소장 : " & 공통!E12 & " (서명)" -> 6. 현장소장 : (서명) | E25: 장비비 | F25: ='5.집행예산산출내역서'!F38/1000 -> 0 | G25: =IFERROR((F25/F9*100),0) -> 0 | H25: ='5.집행예산산출내역서'!G38/1000 -> 0 | I25: =IFERROR((H25/H9*100),0) -> 0 | J25: ='5.집행예산산출내역서'!H38/1000 -> 0 | K25: =IFERROR((J25/J9*100),0) -> 0 | L25: ='5.집행예산산출내역서'!I38/1000 -> 0 | M25: =IFERROR((L25/L9*100),0) -> 0 | N25: ='5.집행예산산출내역서'!J38/1000 -> 0 | O25: =IFERROR((N25/N9*100),0) -> 0 | P25: ='5.집행예산산출내역서'!K38/1000 -> 0 | Q25: =IFERROR((P25/P9*100),0) -> 0 | R25: =N25+P25 -> 0 | S25: =IFERROR((R25/R9*100),0) -> 0 | T25: =J25+L25+R25 -> 0 | U25: =IFERROR((T25/T9*100),0) -> 0
E26: 지급임차비 | F26: ='5.집행예산산출내역서'!F39/1000 -> 0 | G26: =IFERROR((F26/F9*100),0) -> 0 | H26: ='5.집행예산산출내역서'!G39/1000 -> 0 | I26: =IFERROR((H26/H9*100),0) -> 0 | J26: ='5.집행예산산출내역서'!H39/1000 -> 0 | K26: =IFERROR((J26/J9*100),0) -> 0 | L26: ='5.집행예산산출내역서'!I39/1000 -> 0 | M26: =IFERROR((L26/L9*100),0) -> 0 | N26: ='5.집행예산산출내역서'!J39/1000 -> 0 | O26: =IFERROR((N26/N9*100),0) -> 0 | P26: ='5.집행예산산출내역서'!K39/1000 -> 0 | Q26: =IFERROR((P26/P9*100),0) -> 0 | R26: =N26+P26 -> 0 | S26: =IFERROR((R26/R9*100),0) -> 0 | T26: =J26+L26+R26 -> 0 | U26: =IFERROR((T26/T9*100),0) -> 0
E27: 운 반 비 | F27: ='5.집행예산산출내역서'!F40/1000 -> 0 | G27: =IFERROR((F27/F9*100),0) -> 0 | H27: ='5.집행예산산출내역서'!G40/1000 -> 0 | I27: =IFERROR((H27/H9*100),0) -> 0 | J27: ='5.집행예산산출내역서'!H40/1000 -> 0 | K27: =IFERROR((J27/J9*100),0) -> 0 | L27: ='5.집행예산산출내역서'!I40/1000 -> 0 | M27: =IFERROR((L27/L9*100),0) -> 0 | N27: ='5.집행예산산출내역서'!J40/1000 -> 0 | O27: =IFERROR((N27/N9*100),0) -> 0 | P27: ='5.집행예산산출내역서'!K40/1000 -> 0 | Q27: =IFERROR((P27/P9*100),0) -> 0 | R27: =N27+P27 -> 0 | S27: =IFERROR((R27/R9*100),0) -> 0 | T27: =J27+L27+R27 -> 0 | U27: =IFERROR((T27/T9*100),0) -> 0
E28: 회 선 비(CDN) | F28: ='5.집행예산산출내역서'!F41/1000 -> 0 | G28: =IFERROR((F28/F9*100),0) -> 0 | H28: ='5.집행예산산출내역서'!G41/1000 -> 0 | I28: =IFERROR((H28/H9*100),0) -> 0 | J28: ='5.집행예산산출내역서'!H41/1000 -> 0 | K28: =IFERROR((J28/J9*100),0) -> 0 | L28: ='5.집행예산산출내역서'!I41/1000 -> 0 | M28: =IFERROR((L28/L9*100),0) -> 0 | N28: ='5.집행예산산출내역서'!J41/1000 -> 0 | O28: =IFERROR((N28/N9*100),0) -> 0 | P28: ='5.집행예산산출내역서'!K41/1000 -> 0 | Q28: =IFERROR((P28/P9*100),0) -> 0 | R28: =N28+P28 -> 0 | S28: =IFERROR((R28/R9*100),0) -> 0 | T28: =J28+L28+R28 -> 0 | U28: =IFERROR((T28/T9*100),0) -> 0
E29: 소모품비 | F29: ='5.집행예산산출내역서'!F44/1000 -> 0 | G29: =IFERROR((F29/F9*100),0) -> 0 | H29: ='5.집행예산산출내역서'!G44/1000 -> 0 | I29: =IFERROR((H29/H9*100),0) -> 0 | J29: ='5.집행예산산출내역서'!H44/1000 -> 0 | K29: =IFERROR((J29/J9*100),0) -> 0 | L29: ='5.집행예산산출내역서'!I44/1000 -> 0 | M29: =IFERROR((L29/L9*100),0) -> 0 | N29: ='5.집행예산산출내역서'!J44/1000 -> 0 | O29: =IFERROR((N29/N9*100),0) -> 0 | P29: ='5.집행예산산출내역서'!K44/1000 -> 0 | Q29: =IFERROR((P29/P9*100),0) -> 0 | R29: =N29+P29 -> 0 | S29: =IFERROR((R29/R9*100),0) -> 0 | T29: =J29+L29+R29 -> 0 | U29: =IFERROR((T29/T9*100),0) -> 0
E30: 수도광열비 | F30: ='5.집행예산산출내역서'!F47/1000 -> 0 | G30: =IFERROR((F30/F9*100),0) -> 0 | H30: ='5.집행예산산출내역서'!G47/1000 -> 0 | I30: =IFERROR((H30/H9*100),0) -> 0 | J30: ='5.집행예산산출내역서'!H47/1000 -> 0 | K30: =IFERROR((J30/J9*100),0) -> 0 | L30: ='5.집행예산산출내역서'!I47/1000 -> 0 | M30: =IFERROR((L30/L9*100),0) -> 0 | N30: ='5.집행예산산출내역서'!J47/1000 -> 0 | O30: =IFERROR((N30/N9*100),0) -> 0 | P30: ='5.집행예산산출내역서'!K47/1000 -> 0 | Q30: =IFERROR((P30/P9*100),0) -> 0 | R30: =N30+P30 -> 0 | S30: =IFERROR((R30/R9*100),0) -> 0 | T30: =J30+L30+R30 -> 0 | U30: =IFERROR((T30/T9*100),0) -> 0
E31: 여비교통비 | F31: ='5.집행예산산출내역서'!F48/1000 -> 0 | G31: =IFERROR((F31/F9*100),0) -> 0 | H31: ='5.집행예산산출내역서'!G48/1000 -> 0 | I31: =IFERROR((H31/H9*100),0) -> 0 | J31: ='5.집행예산산출내역서'!H48/1000 -> 0 | K31: =IFERROR((J31/J9*100),0) -> 0 | L31: ='5.집행예산산출내역서'!I48/1000 -> 0 | M31: =IFERROR((L31/L9*100),0) -> 0 | N31: ='5.집행예산산출내역서'!J48/1000 -> 0 | O31: =IFERROR((N31/N9*100),0) -> 0 | P31: ='5.집행예산산출내역서'!K48/1000 -> 0 | Q31: =IFERROR((P31/P9*100),0) -> 0 | R31: =N31+P31 -> 0 | S31: =IFERROR((R31/R9*100),0) -> 0 | T31: =J31+L31+R31 -> 0 | U31: =IFERROR((T31/T9*100),0) -> 0
E32: 통 신 비 | F32: ='5.집행예산산출내역서'!F49/1000 -> 0 | G32: =IFERROR((F32/F9*100),0) -> 0 | H32: ='5.집행예산산출내역서'!G49/1000 -> 0 | I32: =IFERROR((H32/H9*100),0) -> 0 | J32: ='5.집행예산산출내역서'!H49/1000 -> 0 | K32: =IFERROR((J32/J9*100),0) -> 0 | L32: ='5.집행예산산출내역서'!I49/1000 -> 0 | M32: =IFERROR((L32/L9*100),0) -> 0 | N32: ='5.집행예산산출내역서'!J49/1000 -> 0 | O32: =IFERROR((N32/N9*100),0) -> 0 | P32: ='5.집행예산산출내역서'!K49/1000 -> 0 | Q32: =IFERROR((P32/P9*100),0) -> 0 | R32: =N32+P32 -> 0 | S32: =IFERROR((R32/R9*100),0) -> 0 | T32: =J32+L32+R32 -> 0 | U32: =IFERROR((T32/T9*100),0) -> 0
E33: 도서인쇄비 | F33: ='5.집행예산산출내역서'!F50/1000 -> 0 | G33: =IFERROR((F33/F9*100),0) -> 0 | H33: ='5.집행예산산출내역서'!G50/1000 -> 0 | I33: =IFERROR((H33/H9*100),0) -> 0 | J33: ='5.집행예산산출내역서'!H50/1000 -> 0 | K33: =IFERROR((J33/J9*100),0) -> 0 | L33: ='5.집행예산산출내역서'!I50/1000 -> 0 | M33: =IFERROR((L33/L9*100),0) -> 0 | N33: ='5.집행예산산출내역서'!J50/1000 -> 0 | O33: =IFERROR((N33/N9*100),0) -> 0 | P33: ='5.집행예산산출내역서'!K50/1000 -> 0 | Q33: =IFERROR((P33/P9*100),0) -> 0 | R33: =N33+P33 -> 0 | S33: =IFERROR((R33/R9*100),0) -> 0 | T33: =J33+L33+R33 -> 0 | U33: =IFERROR((T33/T9*100),0) -> 0
E34: 차량유지비 | F34: ='5.집행예산산출내역서'!F51/1000 -> 0 | G34: =IFERROR((F34/F9*100),0) -> 0 | H34: ='5.집행예산산출내역서'!G51/1000 -> 0 | I34: =IFERROR((H34/H9*100),0) -> 0 | J34: ='5.집행예산산출내역서'!H51/1000 -> 0 | K34: =IFERROR((J34/J9*100),0) -> 0 | L34: ='5.집행예산산출내역서'!I51/1000 -> 0 | M34: =IFERROR((L34/L9*100),0) -> 0 | N34: ='5.집행예산산출내역서'!J51/1000 -> 0 | O34: =IFERROR((N34/N9*100),0) -> 0 | P34: ='5.집행예산산출내역서'!K51/1000 -> 0 | Q34: =IFERROR((P34/P9*100),0) -> 0 | R34: =N34+P34 -> 0 | S34: =IFERROR((R34/R9*100),0) -> 0 | T34: =J34+L34+R34 -> 0 | U34: =IFERROR((T34/T9*100),0) -> 0
E35: 수 수 료 | F35: ='5.집행예산산출내역서'!F52/1000 -> 0 | G35: =IFERROR((F35/F9*100),0) -> 0 | H35: ='5.집행예산산출내역서'!G52/1000 -> 0 | I35: =IFERROR((H35/H9*100),0) -> 0 | J35: ='5.집행예산산출내역서'!H52/1000 -> 0 | K35: =IFERROR((J35/J9*100),0) -> 0 | L35: ='5.집행예산산출내역서'!I52/1000 -> 0 | M35: =IFERROR((L35/L9*100),0) -> 0 | N35: ='5.집행예산산출내역서'!J52/1000 -> 0 | O35: =IFERROR((N35/N9*100),0) -> 0 | P35: ='5.집행예산산출내역서'!K52/1000 -> 0 | Q35: =IFERROR((P35/P9*100),0) -> 0 | R35: =N35+P35 -> 0 | S35: =IFERROR((R35/R9*100),0) -> 0 | T35: =J35+L35+R35 -> 0 | U35: =IFERROR((T35/T9*100),0) -> 0
E36: 안전관리비 | F36: ='5.집행예산산출내역서'!F55/1000 -> 0 | G36: =IFERROR((F36/F9*100),0) -> 0 | H36: ='5.집행예산산출내역서'!G55/1000 -> 0 | I36: =IFERROR((H36/H9*100),0) -> 0 | J36: ='5.집행예산산출내역서'!H55/1000 -> 0 | K36: =IFERROR((J36/J9*100),0) -> 0 | L36: ='5.집행예산산출내역서'!I55/1000 -> 0 | M36: =IFERROR((L36/L9*100),0) -> 0 | N36: ='5.집행예산산출내역서'!J55/1000 -> 0 | O36: =IFERROR((N36/N9*100),0) -> 0 | P36: ='5.집행예산산출내역서'!K55/1000 -> 0 | Q36: =IFERROR((P36/P9*100),0) -> 0 | R36: =N36+P36 -> 0 | S36: =IFERROR((R36/R9*100),0) -> 0 | T36: =J36+L36+R36 -> 0 | U36: =IFERROR((T36/T9*100),0) -> 0 | V36: 안전관리비 정산
E37: 기 타 | F37: ='5.집행예산산출내역서'!F56/1000 -> 0 | G37: =IFERROR((F37/F9*100),0) -> 0 | H37: ='5.집행예산산출내역서'!G56/1000 -> 0 | I37: =IFERROR((H37/H9*100),0) -> 0 | J37: ='5.집행예산산출내역서'!H56/1000 -> 0 | K37: =IFERROR((J37/J9*100),0) -> 0 | L37: ='5.집행예산산출내역서'!I56/1000 -> 0 | M37: =IFERROR((L37/L9*100),0) -> 0 | N37: ='5.집행예산산출내역서'!J56/1000 -> 0 | O37: =IFERROR((N37/N9*100),0) -> 0 | P37: ='5.집행예산산출내역서'!K56/1000 -> 0 | Q37: =IFERROR((P37/P9*100),0) -> 0 | R37: =N37+P37 -> 0 | S37: =IFERROR((R37/R9*100),0) -> 0 | T37: =J37+L37+R37 -> 0 | U37: =IFERROR((T37/T9*100),0) -> 0
E38: 공사비 계 | F38: =F10+F13+F19+F22 -> 0 | G38: =IFERROR((F38/F9*100),0) -> 0 | H38: =H10+H13+H19+H22 -> 0 | I38: =IFERROR((H38/H9*100),0) -> 0 | J38: =J10+J13+J19+J22 -> 0 | K38: =IFERROR((J38/J9*100),0) -> 0 | L38: =L10+L13+L19+L22 -> 0 | M38: =IFERROR((L38/L9*100),0) -> 0 | N38: =N10+N13+N19+N22 -> 0 | O38: =IFERROR((N38/N9*100),0) -> 0 | P38: =P10+P13+P19+P22 -> 0 | Q38: =IFERROR((P38/P9*100),0) -> 0 | R38: =N38+P38 -> 0 | S38: =IFERROR((R38/R9*100),0) -> 0 | T38: =J38+L38+R38 -> 0 | U38: =IFERROR((T38/T9*100),0) -> 0
E39: 간 접 비 | G39: =IFERROR((F39/F9*100),0) -> 0 | H39: =INT(H9*$V$39) -> 0 | I39: =IFERROR((H39/H9*100),0) -> 0 | J39: =INT(J9*$V$39) -> 0 | K39: =IFERROR((J39/J9*100),0) -> 0 | L39: =INT(L9*$V$39) -> 0 | M39: =IFERROR((L39/L9*100),0) -> 0 | N39: =INT(N9*$V$39) -> 0 | O39: =IFERROR((N39/N9*100),0) -> 0 | P39: =INT(P9*$V$39) -> 0 | Q39: =IFERROR((P39/P9*100),0) -> 0 | R39: =P39+N39 -> 0 | S39: =IFERROR((R39/R9*100),0) -> 0 | T39: =J39+L39+R39 -> 0 | U39: =IFERROR((T39/T9*100),0) -> 0 | V39: =공통!E17 -> 0
E40: 일반관리비 | G40: =IFERROR((F40/F9*100),0) -> 0 | H40: =INT(H9*$V$40) -> 0 | I40: =IFERROR((H40/H9*100),0) -> 0 | J40: =INT(J9*$V$40) -> 0 | K40: =IFERROR((J40/J9*100),0) -> 0 | L40: =INT(L9*$V$40) -> 0 | M40: =IFERROR((L40/L9*100),0) -> 0 | N40: =INT(N9*$V$40) -> 0 | O40: =IFERROR((N40/N9*100),0) -> 0 | P40: =INT(P9*$V$40) -> 0 | Q40: =IFERROR((P40/P9*100),0) -> 0 | R40: =P40+N40 -> 0 | S40: =IFERROR((R40/R9*100),0) -> 0 | T40: =J40+L40+R40 -> 0 | U40: =IFERROR((T40/T9*100),0) -> 0 | V40: =공통!E18 -> 0
E41: 금융비용 | G41: =IFERROR((F41/F9*100),0) -> 0 | I41: =IFERROR((H41/H9*100),0) -> 0 | K41: =IFERROR((J41/J9*100),0) -> 0 | M41: =IFERROR((L41/L9*100),0) -> 0 | O41: =IFERROR((N41/N9*100),0) -> 0 | Q41: =IFERROR((P41/P9*100),0) -> 0 | R41: =P41+N41 -> 0 | S41: =IFERROR((R41/R9*100),0) -> 0 | T41: =J41+L41+R41 -> 0 | U41: =IFERROR((T41/T9*100),0) -> 0
E42: 영업이익 | G42: =IFERROR((F42/F9*100),0) -> 0 | H42: =H9-H38-H39-H40-H41 -> 0 | I42: =IFERROR((H42/H9*100),0) -> 0 | J42: =J9-J38-J39-J40-J41 -> 0 | K42: =IFERROR((J42/J9*100),0) -> 0 | L42: =L9-L38-L39-L40-L41 -> 0 | M42: =IFERROR((L42/L9*100),0) -> 0 | N42: =N9-N38-N39-N40-N41 -> 0 | O42: =IFERROR((N42/N9*100),0) -> 0 | P42: =P9-P38-P39-P40-P41 -> 0 | Q42: =IFERROR((P42/P9*100),0) -> 0 | R42: =N42+P42 -> 0 | S42: =IFERROR((R42/R9*100),0) -> 0 | T42: =J42+L42+R42 -> 0 | U42: =IFERROR((T42/T9*100),0) -> 0
D43: `
...

Sheet 5.집행예산산출내역서
C2: 집행예산 산출내역서
C4: ='0. 집행계획(갑지)'!D7 -> 1.공 사 명 : (공사코드: ) | O4: 【단위 : 원】
C5: 비목/계정별 | D5: 산 출 내 역 | F5: 계 약 금 액 | G5: 집 행 금 액 | H5: 정산금액(A) [~25년] | I5: 당기 계획(B) | J5: 당기 이후 | M5: 누계(A+B+C) | N5: 안전관리비 계상금액 (원) | O5: 비고
I6: [26년] | J6: [27년] | K6: [28년~] | L6: 소계 (C)
C7: ■ 재료비 | F7: =SUM(F8:F9) -> 0 | G7: =SUM(G8:G9) -> 0 | H7: =SUM(H8:H9) -> 0 | I7: =SUM(I8:I9) -> 0 | J7: =SUM(J8:J9) -> 0 | K7: =SUM(K8:K9) -> 0 | L7: =J7+K7 -> 0 | M7: =H7+I7+L7 -> 0 | R7: 재료비 탭 참조
C8: - 본사재료비 | D8: 재료비 산출내역 첨부 | F8: =SUMIF('5-1. 재료비산출내역'!$D:$D,1,'5-1. 재료비산출내역'!$J:$J) -> 0 | G8: =SUMIF('5-1. 재료비산출내역'!$D:$D,1,'5-1. 재료비산출내역'!$M:$M) -> 0 | H8: =SUMIF('5-1. 재료비산출내역'!$D:$D,1,'5-1. 재료비산출내역'!$P:$P) -> 0 | I8: =SUMIF('5-1. 재료비산출내역'!$D:$D,1,'5-1. 재료비산출내역'!$S:$S) -> 0 | J8: =SUMIF('5-1. 재료비산출내역'!$D:$D,1,'5-1. 재료비산출내역'!$V:$V) -> 0 | K8: =SUMIF('5-1. 재료비산출내역'!$D:$D,1,'5-1. 재료비산출내역'!$Y:$Y)+SUMIF('5-1. 재료비산출내역'!$D:$D,1,'5-1. 재료비산출내역'!$AB:$AB)+SUMIF('5-1. 재료비산출내역'!$D:$D,1,'5-1. 재료비산출내역'!$AE:$AE) -> 0 | L8: =J8+K8 -> 0 | M8: =H8+I8+L8 -> 0
C9: - 현지재료비 | D9: 재료비 산출내역 첨부 | F9: =SUMIF('5-1. 재료비산출내역'!$D:$D,2,'5-1. 재료비산출내역'!$J:$J) -> 0 | G9: =SUMIF('5-1. 재료비산출내역'!$D:$D,2,'5-1. 재료비산출내역'!$M:$M) -> 0 | H9: =SUMIF('5-1. 재료비산출내역'!$D:$D,2,'5-1. 재료비산출내역'!$P:$P) -> 0 | I9: =SUMIF('5-1. 재료비산출내역'!$D:$D,2,'5-1. 재료비산출내역'!$S:$S) -> 0 | J9: =SUMIF('5-1. 재료비산출내역'!$D:$D,2,'5-1. 재료비산출내역'!$V:$V) -> 0 | K9: =SUMIF('5-1. 재료비산출내역'!$D:$D,2,'5-1. 재료비산출내역'!$Y:$Y)+SUMIF('5-1. 재료비산출내역'!$D:$D,2,'5-1. 재료비산출내역'!$AB:$AB)+SUMIF('5-1. 재료비산출내역'!$D:$D,2,'5-1. 재료비산출내역'!$AE:$AE) -> 0 | L9: =J9+K9 -> 0 | M9: =H9+I9+L9 -> 0
C10: ■ 노무비 | F10: =F11+F13+F15+F17+F19 -> 0 | G10: =G11+G13+G15+G17+G19 -> 0 | H10: =H11+H13+H15+H17+H19 -> 0 | I10: =I11+I13+I15+I17+I19 -> 0 | J10: =J11+J13+J15+J17+J19 -> 0 | K10: =K11+K13+K15+K17+K19 -> 0 | L10: =J10+K10 -> 0 | M10: =H10+I10+L10 -> 0
C11: - 급료(직원) | D11: 소 계 | F11: =SUM(F12:F12) -> 0 | G11: =SUM(G12:G12) -> 0 | H11: =SUM(H12:H12) -> 0 | I11: =SUM(I12:I12) -> 0 | J11: =SUM(J12:J12) -> 0 | K11: =SUM(K12:K12) -> 0 | L11: =J11+K11 -> 0 | M11: =H11+I11+L11 -> 0
D12: =공통!E23 -> 0 | F12: =공통!E24 -> 0 | G12: =공통!E25 -> 0 | H12: =공통!E26 -> 0 | I12: =공통!E27 -> 0 | J12: =공통!E28 -> 0 | K12: =공통!E29 -> 0 | L12: =J12+K12 -> 0 | M12: =H12+I12+L12 -> 0 | R12: 정직원/PJT직군, 부장 7,500,000원, 차장 6,500,000원, 과장 5,500,000원, 대리 4,500,000원, 사원 3,500,000원
C13: - 임금(현장사원) | D13: 소 계 | F13: =SUM(F14:F14) -> 0 | G13: =SUM(G14:G14) -> 0 | H13: =SUM(H14:H14) -> 0 | I13: =SUM(I14:I14) -> 0 | J13: =SUM(J14:J14) -> 0 | K13: =SUM(K14:K14) -> 0 | L13: =J13+K13 -> 0 | M13: =H13+I13+L13 -> 0
C14: 관리직공사원 | D14: =공통!E36 -> 0 | F14: =공통!E37 -> 0 | G14: =공통!E38 -> 0 | H14: =공통!E39 -> 0 | I14: =공통!E40 -> 0 | J14: =공통!E41 -> 0 | K14: =공통!E42 -> 0 | L14: =J14+K14 -> 0 | M14: =H14+I14+L14 -> 0 | R14: 현장사원 급여, 실급여 기준, 현장사원과 장기 계약이 예정돼있는 경우 임금 상승분 고려해야 함
C15: - 상여금(직원) | D15: 소 계 | G15: =SUM(G16:G16) -> 0 | H15: =SUM(H16:H16) -> 0 | I15: =SUM(I16:I16) -> 0 | J15: =SUM(J16:J16) -> 0 | K15: =SUM(K16:K16) -> 0 | L15: =J15+K15 -> 0 | M15: =H15+I15+L15 -> 0 | R15: 정직원/PJT직군, 상여가 지급된 달의 전 달 급여 코드에 반영 - ex. 상여가 1월 25일에 지급 됐다면 12월 급여 코드에 상여금 반영 금액은 1M/M 급여로 책정 - ex. 부장과 과장이 투입 되는 PJT에 추석 상여를 1회 반영한다면 7,500,000원 + 5,500,000원 = 13,000,000원으로 예상 책정
D16: =공통!E30 -> 0 | G16: =공통!E31 -> 0 | H16: =공통!E32 -> 0 | I16: =공통!E33 -> 0 | J16: =공통!E34 -> 0 | K16: =공통!E35 -> 0 | L16: =J16+K16 -> 0 | M16: =H16+I16+L16 -> 0
C17: - 퇴직금(직원) | D17: 소 계 | G17: =SUM(G18:G18) -> 0 | H17: =SUM(H18:H18) -> 0 | I17: =SUM(I18:I18) -> 0 | J17: =SUM(J18:J18) -> 0 | K17: =SUM(K18:K18) -> 0 | L17: =J17+K17 -> 0 | M17: =H17+I17+L17 -> 0 | R17: 정직원/PJT직군, 급여/12, 1년이 되지 않는 직원은 산정X, 단, 1년이 되는 달에 근무하는 사람이 있는 경우 급여 100%
D18: =D12 -> 0 | G18: =(G11+G15)/12 -> 0 | I18: =(I11+I15)/12 -> 0 | L18: =J18+K18 -> 0 | M18: =H18+I18+L18 -> 0
C19: - 퇴직금(현장사원) | D19: 소 계 | G19: =G13/12 -> 0 | H19: =H13/12 -> 0 | I19: =I13/12 -> 0 | J19: =J13/12 -> 0 | K19: =K13/12 -> 0 | L19: =J19+K19 -> 0 | M19: =H19+I19+L19 -> 0 | R19: 현장사원, 급여/12, 1년이 되지 않는 직원은 산정X, 단, 1년이 되는 달에 근무하는 사람이 있는 경우 급여 100%
C20: 관리직공사원 | D20: =D14 -> 0 | L20: =J20+K20 -> 0 | M20: =H20+I20+L20 -> 0
C21: ■ 외주비 | F21: =SUM(F22:F23) -> 0 | G21: =SUM(G22:G23) -> 0 | H21: =SUM(H22:H23) -> 0 | I21: =SUM(I22:I23) -> 0 | J21: =SUM(J22:J23) -> 0 | K21: =SUM(K22:K23) -> 0 | L21: =J21+K21 -> 0 | M21: =H21+I21+L21 -> 0
C22: - 외주용역비 | L22: =J22+K22 -> 0 | M22: =H22+I22+L22 -> 0
C23: - 외주가공비 | L23: =J23+K23 -> 0 | M23: =H23+I23+L23 -> 0
C24: ■ 경 비 | F24: =F25+F26+F38+F39+F40+F41+F44+F47+F48+F49+F50+F51+F52+F55+F56 -> 0 | G24: =G25+G26+G38+G39+G40+G41+G44+G47+G48+G49+G50+G51+G52+G55+G56 -> 0 | H24: =H25+H26+H38+H39+H40+H41+H44+H47+H48+H49+H50+H51+H52+H55+H56 -> 0 | I24: =I25+I26+I38+I39+I40+I41+I44+I47+I48+I49+I50+I51+I52+I55+I56 -> 0 | J24: =J25+J26+J38+J39+J40+J41+J44+J47+J48+J49+J50+J51+J52+J55+J56 -> 0 | K24: =K25+K26+K38+K39+K40+K41+K44+K47+K48+K49+K50+K51+K52+K55+K56 -> 0 | L24: =J24+K24 -> 0 | M24: =H24+I24+L24 -> 0
C25: - 복리후생비 | D25: =공통!E43 -> 0 | F25: =공통!E44 -> 0 | G25: =공통!E45 -> 0 | H25: =공통!E46 -> 0 | I25: =공통!E47 -> 0 | J25: =공통!E48 -> 0 | K25: =공통!E49 -> 0 | L25: =J25+K25 -> 0 | M25: =H25+I25+L25 -> 0 | R25: PJT 기간 간 사용할 비용 산정
C26: - 보험료 | D26: 소 계 | F26: =F27+F33 -> 0 | G26: =G27+G33 -> 0 | H26: =H27+H33 -> 0 | I26: =I27+I33 -> 0 | J26: =J27+J33 -> 0 | K26: =K27+K33 -> 0 | L26: =J26+K26 -> 0 | M26: =H26+I26+L26 -> 0
C27: 보험료(노무) | D27: 25년 기준 | F27: =SUM(F28:F32) -> 0 | G27: =SUM(G28:G32) -> 0 | H27: =SUM(H28:H32) -> 0 | I27: =SUM(I28:I32) -> 0 | J27: =SUM(J28:J32) -> 0 | K27: =SUM(K28:K32) -> 0 | L27: =J27+K27 -> 0 | M27: =H27+I27+L27 -> 0
C28: (국민연금) | D28: ="[총급여액+임금]*" & TEXT(공통!E19, "0.0%") -> [총급여액+임금]*0.0% | G28: =($G$11+$G$13+$G$15)*공통!E19 -> 0 | H28: =($H$11+$H$13+$H$15)*공통!E19 -> 0 | I28: =($I$11+$I$13+$I$15)*공통!E19 -> 0 | J28: =($J$11+$J$13+$J$15)*공통!E19 -> 0 | K28: =($K$11+$K$13+$K$15)*공통!E19 -> 0 | L28: =J28+K28 -> 0 | M28: =H28+I28+L28 -> 0 | R28: 4.5% 기본 요율이나 인사팀에서 변동요율 공지가 있다면 해당 요율로 변경
C29: (건강보험) | D29: ="[총급여액+임금]*" & TEXT(공통!E20, "0.0000%") -> [총급여액+임금]*0.0000% | G29: =($G$11+$G$13+$G$15)*공통!E20 -> 0 | H29: =($H$11+$H$13+$H$15)*공통!E20 -> 0 | I29: =($I$11+$I$13+$I$15)*공통!E20 -> 0 | J29: =($J$11+$J$13+$J$15)*공통!E20 -> 0 | K29: =($K$11+$K$13+$K$15)*공통!E20 -> 0 | L29: =J29+K29 -> 0 | M29: =H29+I29+L29 -> 0 | R29: 매년 초 인사팀에서 요율 공지
C30: (퇴직공제부금) | D30: 적용대상현장적용(계약내역 금액반영)-계약금액 반영(정산대상) | L30: =J30+K30 -> 0 | M30: =H30+I30+L30 -> 0 | R30: 사용X
C31: (산재보험) | D31: ="[총급여액+임금+(외주비*하도급노무비율)]*" & TEXT(공통!E21, "0.000%") -> [총급여액+임금+(외주비*하도급노무비율)]*0.000% | G31: =($G$11+$G$13+$G$15)*공통!E21 -> 0 | H31: =($H$11+$H$13+$H$15)*공통!E21 -> 0 | I31: =($I$11+$I$13+$I$15)*공통!E21 -> 0 | J31: =($J$11+$J$13+$J$15)*공통!E21 -> 0 | K31: =($K$11+$K$13+$K$15)*공통!E21 -> 0 | L31: =J31+K31 -> 0 | M31: =H31+I31+L31 -> 0 | R31: 매년 초 안전보건팀에서 요율 공지
C32: (고용보험) | D32: ="[총급여액+임금+(외주비*하도급노무비율)]*" & TEXT(공통!E22, "0.00%") -> [총급여액+임금+(외주비*하도급노무비율)]*0.00% | G32: =($G$11+$G$13+$G$15)*공통!E22 -> 0 | H32: =($H$11+$H$13+$H$15)*공통!E22 -> 0 | I32: =($I$11+$I$13+$I$15)*공통!E22 -> 0 | J32: =($J$11+$J$13+$J$15)*공통!E22 -> 0 | K32: =($K$11+$K$13+$K$15)*공통!E22 -> 0 | L32: =J32+K32 -> 0 | M32: =H32+I32+L32 -> 0 | R32: 매년 초 안전보건팀에서 요율 공지
C33: 보험료(공사) | F33: =SUM(F34:F37) -> 0 | G33: =SUM(G34:G37) -> 0 | H33: =SUM(H34:H37) -> 0 | I33: =SUM(I34:I37) -> 0 | J33: =SUM(J34:J37) -> 0 | K33: =SUM(K34:K37) -> 0 | L33: =J33+K33 -> 0 | M33: =H33+I33+L33 -> 0 | R33: 계약 사항에 각종 보험 포함된 경우 금액 산정해서 적용
C34: (선급금보증) | L34: =J34+K34 -> 0 | M34: =H34+I34+L34 -> 0
C35: (사용자배상책임보험) | L35: =J35+K35 -> 0 | M35: =H35+I35+L35 -> 0
C36: (계약이행) | D36: 계약이행증권 | L36: =J36+K36 -> 0 | M36: =H36+I36+L36 -> 0 | R36: 영업이 진행하는것인데 보증보험 회사에 컨택해서 고객과의 계약서 금액을 설명하고 대략적인 금액을 물어 봐야함. 해당 금액을 기입. 계약 이후엔 계약서 전체 사본을 PDF로 보내고 실제 비용 회신 및 결재/증권 받아야 함. 이때 영업이 보증보험 담당자에게 하자이행 보험료가 대약 얼마일지 확인해서 PM에게 알려줘야함)
C37: (하자이행) | D37: 하자이행증권 | L37: =J37+K37 -> 0 | M37: =H37+I37+L37 -> 0 | R37: PM이 영업에게 전달받은 대략적인 금액을 기입하고 프로젝트 완료시 PM이 하자이행 증권 끊어야 함.
C38: - 장비비 | D38: =공통!E64 -> 0 | F38: =공통!E65 -> 0 | G38: =공통!E66 -> 0 | H38: =공통!E67 -> 0 | I38: =공통!E68 -> 0 | J38: =공통!E69 -> 0 | K38: =공통!E70 -> 0 | L38: =J38+K38 -> 0 | M38: =H38+I38+L38 -> 0
C39: - 지급임차료 | D39: =공통!E71 -> 0 | F39: =공통!E72 -> 0 | G39: =공통!E73 -> 0 | H39: =공통!E74 -> 0 | I39: =공통!E75 -> 0 | J39: =공통!E76 -> 0 | K39: =공통!E77 -> 0 | L39: =J39+K39 -> 0 | M39: =H39+I39+L39 -> 0 | R39: PJT룸 임차, 노트북 임차 등 구매가 아닌 임차로 사용하는 경우 금액 산정
C40: - 운반비 | D40: =공통!E78 -> 0 | F40: =공통!E79 -> 0 | G40: =공통!E80 -> 0 | H40: =공통!E81 -> 0 | I40: =공통!E82 -> 0 | J40: =공통!E83 -> 0 | K40: =공통!E84 -> 0 | L40: =J40+K40 -> 0 | M40: =H40+I40+L40 -> 0
C41: - 회선비(CDN) | D41: 소 계 | F41: =SUM(F42:F43) -> 0 | G41: =SUM(G42:G43) -> 0 | H41: =SUM(H42:H43) -> 0 | I41: =SUM(I42:I43) -> 0 | J41: =SUM(J42:J43) -> 0 | K41: =SUM(K42:K43) -> 0 | L41: =J41+K41 -> 0 | M41: =H41+I41+L41 -> 0
C42: Cloud사용료 | D42: 회선비 산출내역 첨부 | F42: =SUMIF('5-2. 회선비산출내역'!$D:$D,1,'5-2. 회선비산출내역'!$J:$J) -> 0 | G42: =SUMIF('5-2. 회선비산출내역'!$D:$D,1,'5-2. 회선비산출내역'!$M:$M) -> 0 | H42: =SUMIF('5-2. 회선비산출내역'!$D:$D,1,'5-2. 회선비산출내역'!$P:$P) -> 0 | I42: =SUMIF('5-2. 회선비산출내역'!$D:$D,1,'5-2. 회선비산출내역'!$S:$S) -> 0 | J42: =SUMIF('5-2. 회선비산출내역'!$D:$D,1,'5-2. 회선비산출내역'!$V:$V) -> 0 | K42: =SUMIF('5-2. 회선비산출내역'!$D:$D,1,'5-2. 회선비산출내역'!$Y:$Y)+SUMIF('5-2. 회선비산출내역'!$D:$D,1,'5-2. 회선비산출내역'!$AB:$AB)+SUMIF('5-2. 회선비산출내역'!$D:$D,1,'5-2. 회선비산출내역'!$AE:$AE) -> 0 | L42: =J42+K42 -> 0 | M42: =H42+I42+L42 -> 0
...

Sheet 5-4. 수수료산출내역
O1: 3
D2: [ ■ 본사 □ 현지 ] 재료비 산출내역
D3: 수수료 산출내역(1=용역 수수료, 2=유지보수 수수료)
D4: ='0. 집행계획(갑지)'!D7 -> 1.공 사 명 : (공사코드: ) | AJ4: 【단위 : 원】
D5: 자재 코드 | E5: 품 명 | F5: 규 격 | G5: 단위 | H5: 계 약 | K5: 집행계획(A) | N5: 정산누계(B) [~25년] | Q5: 당기계획(C) [26년] | T5: 당기 이후 | AH5: 계(E=B+C+D) | AJ5: 비 고
T6: [27년] | W6: [28년] | Z6: [29년] | AC6: [30년] | AF6: 소계(D)
H7: 수량 | I7: 단가 | J7: 금액 | K7: 수량 | L7: 단가 | M7: 금액 | N7: 수량 | O7: 단가 | P7: 금액 | Q7: 수량 | R7: 단가 | S7: 금액 | T7: 수량 | U7: 단가 | V7: 금액 | W7: 수량 | X7: 단가 | Y7: 금액 | Z7: 수량 | AA7: 단가 | AB7: 금액 | AC7: 수량 | AD7: 단가 | AE7: 금액 | AF7: 수량 | AG7: 금액 | AH7: 수량 | AI7: 금액
J8: =H8*I8 | M8: =K8*L8 | P8: =N8*O8 -> 0 | S8: =Q8*R8 -> 72000000 | V8: =T8*U8 -> 0 | Y8: =W8*X8 -> 0 | AB8: =Z8*AA8 -> 0 | AE8: =AC8*AD8 -> 0 | AF8: =T8+W8+Z8+AC8 -> 0 | AG8: =V8+Y8+AB8+AE8 -> 0 | AH8: =AF8+Q8+N8 -> 9 | AI8: =AG8+S8+P8 -> 72000000 | AL8: =AI8-M8
M9: =K9*L9 -> 0 | P9: =N9*O9 -> 0 | S9: =Q9*R9 -> 0 | V9: =T9*U9 -> 0 | Y9: =W9*X9 -> 0 | AB9: =Z9*AA9 -> 0 | AE9: =AC9*AD9 -> 0 | AF9: =T9+W9+Z9+AC9 -> 0 | AG9: =V9+Y9+AB9+AE9 -> 0 | AH9: =AF9+Q9+N9 -> 0 | AI9: =AG9+S9+P9 -> 0 | AL9: =AI9-M9 -> 0
J10: =H10*I10 -> 0 | M10: =K10*L10 -> 0 | P10: =N10*O10 -> 0 | S10: =Q10*R10 -> 0 | V10: =T10*U10 -> 0 | Y10: =W10*X10 -> 0 | AB10: =Z10*AA10 -> 0 | AE10: =AC10*AD10 -> 0 | AF10: =T10+W10+Z10+AC10 -> 0 | AG10: =V10+Y10+AB10+AE10 -> 0 | AH10: =AF10+Q10+N10 -> 0 | AI10: =AG10+S10+P10 -> 0 | AL10: =AI10-M10 -> 0
J11: =H11*I11 -> 0 | M11: =K11*L11 -> 0 | P11: =N11*O11 -> 0 | S11: =Q11*R11 -> 0 | V11: =T11*U11 -> 0 | Y11: =W11*X11 -> 0 | AB11: =Z11*AA11 -> 0 | AE11: =AC11*AD11 -> 0 | AF11: =T11+W11+Z11+AC11 -> 0 | AG11: =V11+Y11+AB11+AE11 -> 0 | AH11: =AF11+Q11+N11 -> 0 | AI11: =AG11+S11+P11 -> 0 | AL11: =AI11-M11 -> 0
J12: =H12*I12 -> 0 | M12: =K12*L12 -> 0 | P12: =N12*O12 -> 0 | S12: =Q12*R12 -> 0 | V12: =T12*U12 -> 0 | Y12: =W12*X12 -> 0 | AB12: =Z12*AA12 -> 0 | AE12: =AC12*AD12 -> 0 | AF12: =T12+W12+Z12+AC12 -> 0 | AG12: =V12+Y12+AB12+AE12 -> 0 | AH12: =AF12+Q12+N12 -> 0 | AI12: =AG12+S12+P12 -> 0 | AL12: =AI12-M12 -> 0
J13: =H13*I13 -> 0 | M13: =K13*L13 -> 0 | P13: =N13*O13 -> 0 | S13: =Q13*R13 -> 0 | V13: =T13*U13 -> 0 | Y13: =W13*X13 -> 0 | AB13: =Z13*AA13 -> 0 | AE13: =AC13*AD13 -> 0 | AF13: =T13+W13+Z13+AC13 -> 0 | AG13: =V13+Y13+AB13+AE13 -> 0 | AH13: =AF13+Q13+N13 -> 0 | AI13: =AG13+S13+P13 -> 0 | AL13: =AI13-M13 -> 0
J14: =H14*I14 -> 0 | M14: =K14*L14 -> 0 | P14: =N14*O14 -> 0 | S14: =Q14*R14 -> 0 | V14: =T14*U14 -> 0 | Y14: =W14*X14 -> 0 | AB14: =Z14*AA14 -> 0 | AE14: =AC14*AD14 -> 0 | AF14: =T14+W14+Z14+AC14 -> 0 | AG14: =V14+Y14+AB14+AE14 -> 0 | AH14: =AF14+Q14+N14 -> 0 | AI14: =AG14+S14+P14 -> 0 | AL14: =AI14-M14 -> 0
J15: =H15*I15 -> 0 | M15: =K15*L15 -> 0 | P15: =N15*O15 -> 0 | S15: =Q15*R15 -> 0 | V15: =T15*U15 -> 0 | Y15: =W15*X15 -> 0 | AB15: =Z15*AA15 -> 0 | AE15: =AC15*AD15 -> 0 | AF15: =T15+W15+Z15+AC15 -> 0 | AG15: =V15+Y15+AB15+AE15 -> 0 | AH15: =AF15+Q15+N15 -> 0 | AI15: =AG15+S15+P15 -> 0 | AL15: =AI15-M15 -> 0
J16: =H16*I16 -> 0 | M16: =K16*L16 -> 0 | P16: =N16*O16 -> 0 | S16: =Q16*R16 -> 0 | V16: =T16*U16 -> 0 | Y16: =W16*X16 -> 0 | AB16: =Z16*AA16 -> 0 | AE16: =AC16*AD16 -> 0 | AF16: =T16+W16+Z16+AC16 -> 0 | AG16: =V16+Y16+AB16+AE16 -> 0 | AH16: =AF16+Q16+N16 -> 0 | AI16: =AG16+S16+P16 -> 0 | AL16: =AI16-M16 -> 0
D17: 합 계 | J17: =SUM(J8:J16) -> 0 | M17: =SUM(M8:M16) -> 0 | P17: =SUM(P8:P16) -> 0 | S17: =SUM(S8:S16) -> 72000000 | V17: =SUM(V8:V16) -> 0 | Y17: =SUM(Y8:Y16) -> 0 | AB17: =SUM(AB8:AB16) -> 0 | AE17: =SUM(AE8:AE16) -> 0 | AG17: =SUM(AG8:AG16) -> 0 | AI17: =SUM(AI8:AI16) -> 72000000 | AL17: =AI17-M17 -> 72000000
D19: GS네오텍 | G19: Page : | AJ19: GP-4050-07(1)

Sheet 1. 현장조직_업무분장
C4: 현장조직 및 업무분장
D5: ='0. 집행계획(갑지)'!D7 -> 1.공 사 명 : (공사코드: )
Y7: 현 장 소 장
Y8: 직위 : | AD8: 성명 :
Y10: 1.시공 및 QES 총괄
Y11: 2.계약 및 기성관리
Y12: 3.대외영업활동
Y13: 4.관련법규 및 대관인허가업무
G18: 시공/기술담당 : | Y18: 품질담당 : | AQ18: 안전담당 :
G20: 1.시공/작업계획수립 및 실시 | Y20: 1.검사 및 시험계획 수립,시행 | AQ20: 1.안전관리계획수립 및 실시
G21: 2.공정관리 및 공법개선 | Y21: 2.부적합보고서작성 및 이행 | AQ21: 2.재해예방활동 및 교육실시
G22: 3.기술교육실시,안전예방조치 | Y22: 3.문서 및 기록 관리 | AQ22: 3.안전관리직무수행
G26: 소방,자재관리담당 : | Y26: 소방/공무담당 : | AQ26: 기타 : 경비,경리 등
G28: 1.자재수급계획수립 및 청구 | Y28: 1.현장행정 및 본사행정 관리 | AQ28: 1.도난 및 화재경비
G29: 2.입출고관리,고객지급품관리 | Y29: 2.집행예산관리 | AQ29: 2.경리업무, 행정보조
G30: 3.부적합자재 시정조치,관리 | Y30: 3.공정부진시 만회대책수립 | AQ30: 3.물자운반, 작업보조
D34: ※ 공사규모, 현장여건, 소장능력 등을 고려하여 통합,분할할 수 있음
C35: GS네오텍 Page : | BH35: GP-4050-02(1)

Sheet 2. 공사개요
D4: 공 사 개 요
D5: ='0. 집행계획(갑지)'!D7 -> 1.공 사 명 : (공사코드: )
D6: 1-1. 주요공종
D7: 공 종 별 | E7: 가중치 | F7: 단위 | G7: 수량 | H7: 비 고
F9: 식 | G9: 1
F10: 식 | G10: 1
F11: 식 | G11: 1
F12: 식 | G12: 1
F13: 식 | G13: 1
F14: 식 | G14: 1
D29: 합 계 | E29: =E8+E11+E14 -> 0
D30: 1-2. 현장위치
D31: 위 치 :
D36: 1-3. 현장 표준근로기준
D37: ※ 일일표준근로시간, 월근무일수, 추가근무지급기준, 년/월차 포함여부, 기타조건
D38: 1. 일일 8시간근무 AM 07:00 ~ PM 05:00 (중식 1시간, 오전/오후 30분 휴무)
D39: 2. 주 6일근무 (주 1회휴무)
D43: GS네오텍 | F43: Page : | H43: GP-4050-03(1)

Sheet 3.예정공정표
A2: 전 기 공 사 전 체 공 정 표
A3: 공사명 : 운서역 복합시설 신축 전기 소방공사 ('15.06.01- '17.04.30) | CY3: 현장 책임자 : 한 상 욱 (인)
CY4: 작성일 : 2015년 01월 15일
A5: 구 분 | C5: 중 공 종 | D5: 소 공 종 | E5: 금 액 | F5: 보할 | G5: 2015년 | AI5: 2016년 | CE5: 2017년 | CY5: 비 고
H6: 6월 | L6: 7월 | P6: 8월 | T6: 9월 | X6: 10월 | AB6: 11월 | AF6: 12월 | AJ6: 1월 | AN6: 2월 | AR6: 3월 | AV6: 4월 | AZ6: 5월 | BD6: 6월 | BH6: 7월 | BL6: 8월 | BP6: 9월 | BT6: 10월 | BX6: 11월 | CB6: 12월 | CF6: 1월 | CJ6: 2월 | CN6: 3월 | CR6: 4월 | CV6: 5월
G7: 1 | H7: 2 | I7: 3 | J7: 4 | K7: 1 | L7: 2 | M7: 3 | N7: 4 | O7: 1 | P7: 2 | Q7: 3 | R7: 4 | S7: 1 | T7: 2 | U7: 3 | V7: 4 | W7: 1 | X7: 2 | Y7: 3 | Z7: 4 | AA7: 1 | AB7: 2 | AC7: 3 | AD7: 4 | AE7: 1 | AF7: 2 | AG7: 3 | AH7: 4 | AI7: 1 | AJ7: 2 | AK7: 3 | AL7: 4 | AM7: 1 | AN7: 2 | AO7: 3 | AP7: 4 | AQ7: 1 | AR7: 2 | AS7: 3 | AT7: 4 | AU7: 1 | AV7: 2 | AW7: 3 | AX7: 4 | AY7: 1 | AZ7: 2 | BA7: 3 | BB7: 4 | BC7: 1 | BD7: 2 | BE7: 3 | BF7: 4 | BG7: 1 | BH7: 2 | BI7: 3 | BJ7: 4 | BK7: 1 | BL7: 2 | BM7: 3 | BN7: 4 | BO7: 1 | BP7: 2 | BQ7: 3 | BR7: 4 | BS7: 1 | BT7: 2 | BU7: 3 | BV7: 4 | BW7: 1 | BX7: 2 | BY7: 3 | BZ7: 4 | CA7: 1 | CB7: 2 | CC7: 3 | CD7: 4 | CE7: 1 | CF7: 2 | CG7: 3 | CH7: 4 | CI7: 1 | CJ7: 2 | CK7: 3 | CL7: 4 | CM7: 1 | CN7: 2 | CO7: 3 | CP7: 4 | CQ7: 1 | CR7: 2 | CS7: 3 | CT7: 4 | CU7: 1 | CV7: 2 | CW7: 3 | CX7: 4
B8: 토 목 | C8: -.가설공사 | D8: -.가설공사 | Y8: T/C설치-1 | AF8: T/C설치-2 | BC8: H/C설치 | BS8: T/C설치 | CA8: H/C해체
A9: 건 | C9: -.가시설공사 | D9: -.가시설공사 | I9: CIP굴착 | T9: E/A 앙카 시공 | AJ9: E/A 해체 | BC9: - 내부 조적 및 단열공사
A10: 축 | C10: -.토공사 | D10: -.토공사 | U10: 토사반출
A11: 공 | B11: 건 축 | C11: -.골조공사 | D11: -.골조공사 | AA11: 골조공사 | AE11: B3F | AM11: B2F | AQ11: B1F | AT11: 1F | AV11: 2F | AY11: PIT | BB11: 3F | BD11: 4F | BG11: 5F | BI11: 6F | BK11: 7F | BL11: 8F | BN11: 9F | BP11: 10F
A12: 사 | C12: -.조적공사 | D12: -.조적공사 | AV12: 지하층/1,2층 조적 | BC12: 3 ~ 6층 내부 조적(ALC, 시멘트벽돌) | BL12: 7 ~ 10층 내부 조적(ALC, 시멘트벽돌) | BT12: 외부/옥상조적
C13: -.내장공사 | D13: -.내장공사 | BG13: 벽체/천정 작업(3 ~ 6층) | BN13: 벽체/천정 작업(7 ~ 10층) | BU13: 걸레받이 및 천정몰딩 | CA13: 판매시설 경량 벽체/천정
C14: -.마감공사 | D14: -.마감공사 | BR14: 세대천정도장 | BY14: 벽체/천정 도배 | CF14: 가구 및 마루 작업 | CN14: 가전설치
A15: 대 관 업 무 | C15: -.전기공사계획신고 | D15: -.전기공사계획신고 | AJ15: 공사계획신고 | AQ15: 신고수리필증 | CY15: *.한국전기안전공사
C16: -.한전 수용신청 | D16: -.한전 수용신청 | AJ16: 한전수용신청 | CY16: *.한국전력공사
C17: -.전기사용전검사(전기실,단위세대) | D17: -.전기사용전검사(전기실,단위세대) | CD17: 사용전검사(고압) | CN17: 사용전검사(저압) | CY17: *.한국전기안전공사
C18: -.한전수전 | D18: -.한전수전 | CF18: 한전수전 | CY18: *.한국전력공사
C19: -.소방착공신고및준공검사 | D19: -.소방착공신고및준공검사 | AB19: 소방착공신고 | CO19: 소방준공검사 | CY19: *.소방서
A20: 전 기 공 사 | B20: 전 기 공 사 | C20: 01.옥외보안등설비공사 | D20: 옥외보안등설비공사 | E20: 10972464 | F20: 0.0013 | CC20: 옥외배관 | CH20: 케이블 배선 | CN20: 보안등설치
C21: 02.수변전설비공사 | D21: 배관공사 | E21: 15341683 | F21: 0.0019 | BL21: 인입맨홀, 배관 | CA21: 요청검사 | CD21: 사용전검사(고압)
D22: 배선공사 | E22: 43599595 | F22: 0.0053 | BT22: 배선,HEAD 단말
D23: BUS DUCT 설치공사 | E23: 196339441 | F23: 0.0238 | BT23: BUS DUCT 설치
D24: 수배전반, 발전기 설치공사 | E24: 1010560681 | F24: 0.1225 | BP24: 발젅기입고 | BR24: 수배전반입고
C25: 03.전력간선설비공사 | D25: 배관공사 | E25: 148246448 | F25: 0.018 | BL25: 전력간선 노출배관
D26: CABLE 배선공사 | E26: 593656703 | F26: 0.072 | BJ26: 전력간선 케이블 포설
D27: 분전반 설치공사 | E27: 329828776 | F27: 0.04 | AZ27: B3F ~ B1F 분전반설치 | BP27: 3F ~ 10F 분전반설치 | CB27: 1F ~2F 판매시설 분전반 설치
C28: 04.동력설비공사 | D28: 노출배관공사 | E28: 39460096 | F28: 0.0048 | BF28: 지하층 휀룸,공조실 노출배관 | BP28: 기계, 전기실 노출배관 | CB28: 지상층 웬룸, 공조실 노출배관
D29: 배선공사 | E29: 87759239 | F29: 0.0106 | BH29: 지하층 휀룸,공조실 배선 및 결선 | BS29: 기계, 전기실 배선 및 결선 | CE29: 지상층 웬룸, 공조실 배선 및 결선
C30: 05.단위세대전기공사 | D30: 매입배관공사 | E30: 268080045 | F30: 0.0325 | BB30: 3F | BD30: 4F | BG30: 5F | BI30: 6F | BK30: 7F | BL30: 8F | BN30: 9F | BP30: 10F
D31: 배선공사 | E31: 223862154 | F31: 0.0271 | BH31: 3F ~ 7F | BP31: 8F ~ 10F
D32: 기구취부공사 | E32: 942864471 | F32: 0.1143 | BZ32: 3F ~5F 전등,기구취부 | CD32: 6F ~8F 전등,기구취부 | CH32: 9F ~10F 전등,기구취부
C33: 06.전등설비공사 | D33: 매입배관공사 | E33: 185113275 | F33: 0.0225 | AE33: B3F | AM33: B2F | AQ33: B1F | AT33: 1F | AV33: 2F | AY33: PIT | BB33: 3F | BD33: 4F | BG33: 5F | BI33: 6F | BK33: 7F | BL33: 8F | BN33: 9F | BP33: 10F
D34: 배선공사 | E34: 109628744 | F34: 0.0133 | AR34: 지하 B3F ~ B1F | BA34: 1F ~ 3F | BH34: 4F ~ 6F | BP34: 7F ~ 10F
D35: 기구취부공사 | E35: 264332131 | F35: 0.0321 | BO35: 전기,기계실 RACEWAY등 취부 | BW35: 주차장 RACEWAY등 취부 | CB35: 3F ~6F 공용 취부 | CF35: 7F ~ 10F 공용 취부 | CJ35: 1 ~2F 공용 및 상가취부
C36: 07.전열설비공사 | D36: 매입배관공사 | E36: 18269456 | F36: 0.0022 | AE36: B3F | AM36: B2F | AQ36: B1F | AT36: 1F | AV36: 2F | AY36: PIT | BB36: 3F | BD36: 4F | BG36: 5F | BI36: 6F | BK36: 7F | BL36: 8F | BN36: 9F | BP36: 10F
D37: 배선공사 | E37: 22944624 | F37: 0.0028 | AR37: 지하 B3F ~ B1F | BA37: 1F ~ 3F | BH37: 4F ~ 6F | BP37: 7F ~ 10F
D38: 기구취부공사 | E38: 20105314 | F38: 0.0024 | BO38: 전기,기계실 기구 취부 | BW38: 주차장 기구 취부 | BZ38: 3F ~6F 공용 취부 | CD38: 7F ~ 10F 공용 취부 | CH38: 1 ~2F 공용 및 상가취부
C39: 08.전력제어설비공사 | D39: 노출배관공사 | E39: 9392796 | F39: 0.0011 | BY39: 노출배관
D40: 배선공사 | E40: 4399289 | F40: 0.0005 | CA40: 간선 케이블 배선
D41: 시스템 설치공사 | E41: 31947545 | F41: 0.0039 | CD41: 전기실 장비 설치/결선 | CI41: 감시실 장비설치/결선
...

Sheet 3. 예정공정표
C4: 예 정 공 정 표
C6: ='0. 집행계획(갑지)'!D7 -> 1.공 사 명 : (공사코드: )
C7: 공 종 | E7: 단위 | F7: 공정량 | G7: 보할 | H7: 공 사 기 간 | AG7: 비 고
H8: 00년 | T8: 00년 | AF8: 00년
H9: 1월 | I9: 2월 | J9: 3월 | K9: 4월 | L9: 5월 | M9: 6월 | N9: 7월 | O9: 8월 | P9: 9월 | Q9: 10월 | R9: 11월 | S9: 12월 | T9: 1월 | U9: 2월 | V9: 3월 | W9: 4월 | X9: 5월 | Y9: 6월 | Z9: 7월 | AA9: 8월 | AB9: 9월 | AC9: 10월 | AD9: 11월 | AE9: 12월 | AF9: 1월
H10: 1M | I10: 2M | J10: 3M | K10: 4M | L10: 5M | M10: 6M | N10: 7M | O10: 8M | P10: 9M | Q10: 10M | R10: 11M | S10: 12M | T10: 13M | U10: 14M | V10: 15M | W10: 16M | X10: 17M | Y10: 18M | Z10: 19M | AA10: 20M | AB10: 21M | AC10: 22M | AD10: 23M | AE10: 24M | AF10: 25M
C59: 계 | G59: =SUM(G11:G58) -> 0
C61: GS네오텍 | G61: Page : | AG61: GP-4050-04(1)

Sheet 인원투입계획
B2: 급여
B3: 구분 | E3: 년 | Q3: 년 | AE3: 년 | AQ3: 합계 | AR3: 금액
B4: 성명 | C4: 직위 | D4: 급여 | E4: 3월 | F4: 4월 | G4: 5월 | H4: 6월 | I4: 7월 | J4: 8월 | K4: 9월 | L4: 10월 | M4: 11월 | N4: 12월 | O4: 소계 | P4: 금액 | Q4: 1월 | R4: 2월 | S4: 3월 | T4: 4월 | U4: 5월 | V4: 6월 | W4: 7월 | X4: 8월 | Y4: 9월 | Z4: 10월 | AA4: 11월 | AB4: 12월 | AC4: 소계 | AD4: 금액 | AE4: 1월 | AF4: 2월 | AG4: 3월 | AH4: 4월 | AI4: 5월 | AJ4: 6월 | AK4: 7월 | AL4: 8월 | AM4: 9월 | AN4: 10월 | AO4: 소계 | AP4: 금액
A5: 간접비
B11: 소계
A13: 직접비
C23: 하자/정리
C24: 하자/정리
B25: 소계 | D25: =SUM(D13:D22)/12 -> 0
B37: 소계
B39: 합계
B41: 상여
B42: 구분 | E42: 년 | Q42: 년 | AE42: 년 | AQ42: 합계 | AR42: 금액
B43: 성명 | C43: 직위 | D43: 급여 | E43: 3월 | F43: 4월 | G43: 5월 | H43: 6월 | I43: 7월 | J43: 8월 | K43: 9월 | L43: 10월 | M43: 11월 | N43: 12월 | O43: 소계 | P43: 금액 | Q43: 1월 | R43: 2월 | S43: 3월 | T43: 4월 | U43: 5월 | V43: 6월 | W43: 7월 | X43: 8월 | Y43: 9월 | Z43: 10월 | AA43: 11월 | AB43: 12월 | AC43: 소계 | AD43: 금액 | AE43: 1월 | AF43: 2월 | AG43: 3월 | AH43: 4월 | AI43: 5월 | AJ43: 6월 | AK43: 7월 | AL43: 8월 | AM43: 9월 | AN43: 10월 | AO43: 소계 | AP43: 금액
A44: 직원
B45: 소계
B47: 퇴직금
B48: 구분 | E48: 년 | Q48: 년 | AE48: 년 | AQ48: 합계 | AR48: 금액
B49: 성명 | C49: 직위 | D49: 급여 | E49: 3월 | F49: 4월 | G49: 5월 | H49: 6월 | I49: 7월 | J49: 8월 | K49: 9월 | L49: 10월 | M49: 11월 | N49: 12월 | O49: 소계 | P49: 금액 | Q49: 1월 | R49: 2월 | S49: 3월 | T49: 4월 | U49: 5월 | V49: 6월 | W49: 7월 | X49: 8월 | Y49: 9월 | Z49: 10월 | AA49: 11월 | AB49: 12월 | AC49: 소계 | AD49: 금액 | AE49: 1월 | AF49: 2월 | AG49: 3월 | AH49: 4월 | AI49: 5월 | AJ49: 6월 | AK49: 7월 | AL49: 8월 | AM49: 9월 | AN49: 10월 | AO49: 소계 | AP49: 금액
A50: 직원
B51: 소계
B52: 퇴직금
B53: 구분 | E53: 년 | Q53: 년 | AE53: 년 | AQ53: 합계 | AR53: 금액
B54: 성명 | C54: 직위 | D54: 급여 | E54: 3월 | F54: 4월 | G54: 5월 | H54: 6월 | I54: 7월 | J54: 8월 | K54: 9월 | L54: 10월 | M54: 11월 | N54: 12월 | O54: 소계 | P54: 금액 | Q54: 1월 | R54: 2월 | S54: 3월 | T54: 4월 | U54: 5월 | V54: 6월 | W54: 7월 | X54: 8월 | Y54: 9월 | Z54: 10월 | AA54: 11월 | AB54: 12월 | AC54: 소계 | AD54: 금액 | AE54: 1월 | AF54: 2월 | AG54: 3월 | AH54: 4월 | AI54: 5월 | AJ54: 6월 | AK54: 7월 | AL54: 8월 | AM54: 9월 | AN54: 10월 | AO54: 소계 | AP54: 금액
A55: 간접비
B61: 소계
A63: 직접비
C73: 하자/정리
C74: 하자/정리
B75: 소계 | D75: =SUM(D63:D74)/12 -> 0
B77: 합계
B79: 주재수당
B80: 구분 | E80: 년 | Q80: 년 | AE80: 년 | AQ80: 합계 | AR80: 금액
B81: 성명 | C81: 직위 | D81: 주재비 | E81: 3월 | F81: 4월 | G81: 5월 | H81: 6월 | I81: 7월 | J81: 8월 | K81: 9월 | L81: 10월 | M81: 11월 | N81: 12월 | O81: 소계 | P81: 금액 | Q81: 1월 | R81: 2월 | S81: 3월 | T81: 4월 | U81: 5월 | V81: 6월 | W81: 7월 | X81: 8월 | Y81: 9월 | Z81: 10월 | AA81: 11월 | AB81: 12월 | AC81: 소계 | AD81: 금액 | AE81: 1월 | AF81: 2월 | AG81: 3월 | AH81: 4월 | AI81: 5월 | AJ81: 6월 | AK81: 7월 | AL81: 8월 | AM81: 9월 | AN81: 10월 | AO81: 소계 | AP81: 금액
B83: 소계
B85: 주부식대
B86: 구분 | E86: 년 | Q86: 년 | AE86: 년 | AQ86: 합계 | AR86: 금액
B87: 성명 | C87: 직위 | D87: 1식 | E87: 3월 | F87: 4월 | G87: 5월 | H87: 6월 | I87: 7월 | J87: 8월 | K87: 9월 | L87: 10월 | M87: 11월 | N87: 12월 | O87: 소계 | P87: 금액 | Q87: 1월 | R87: 2월 | S87: 3월 | T87: 4월 | U87: 5월 | V87: 6월 | W87: 7월 | X87: 8월 | Y87: 9월 | Z87: 10월 | AA87: 11월 | AB87: 12월 | AC87: 소계 | AD87: 금액 | AE87: 1월 | AF87: 2월 | AG87: 3월 | AH87: 4월 | AI87: 5월 | AJ87: 6월 | AK87: 7월 | AL87: 8월 | AM87: 9월 | AN87: 10월 | AO87: 소계 | AP87: 금액
A88: 간접비
B94: 소계
...

Sheet 5-1. 재료비산출내역
O1: 3
D2: [ ■ 본사 □ 현지 ] 재료비 산출내역
D3: 재료비 산출내역(1=본사 재료비, 2=현지 재료비)
D4: ='0. 집행계획(갑지)'!D7 -> 1.공 사 명 : (공사코드: ) | AJ4: 【단위 : 원】
D5: 자재 코드 | E5: 품 명 | F5: 규 격 | G5: 단위 | H5: 계 약 | K5: 집행계획(A) | N5: 정산누계(B) [~25년] | Q5: 당기계획(C) [26년] | T5: 당기 이후 | AH5: 계(E=B+C+D) | AJ5: 비 고
T6: [27년] | W6: [28년] | Z6: [29년] | AC6: [30년~] | AF6: 소계(D)
H7: 수량 | I7: 단가 | J7: 금액 | K7: 수량 | L7: 단가 | M7: 금액 | N7: 수량 | O7: 단가 | P7: 금액 | Q7: 수량 | R7: 단가 | S7: 금액 | T7: 수량 | U7: 단가 | V7: 금액 | W7: 수량 | X7: 단가 | Y7: 금액 | Z7: 수량 | AA7: 단가 | AB7: 금액 | AC7: 수량 | AD7: 단가 | AE7: 금액 | AF7: 수량 | AG7: 금액 | AH7: 수량 | AI7: 금액
J8: =H8*I8 -> 0 | M8: =K8*L8 -> 0 | P8: =N8*O8 -> 0 | S8: =Q8*R8 -> 0 | V8: =T8*U8 -> 0 | Y8: =W8*X8 -> 0 | AB8: =Z8*AA8 -> 0 | AE8: =AC8*AD8 -> 0 | AF8: =T8+W8+Z8+AC8 -> 0 | AG8: =V8+Y8+AB8+AE8 -> 0 | AH8: =AF8+Q8+N8 -> 0 | AI8: =AG8+S8+P8 -> 0 | AM8: 자재코드(D열) : 1 (Cloud사용료), 2(라이선스)
J9: =H9*I9 -> 0 | M9: =K9*L9 -> 0 | P9: =N9*O9 -> 0 | S9: =Q9*R9 -> 0 | V9: =T9*U9 -> 0 | Y9: =W9*X9 -> 0 | AB9: =Z9*AA9 -> 0 | AE9: =AC9*AD9 -> 0 | AF9: =T9+W9+Z9+AC9 -> 0 | AG9: =V9+Y9+AB9+AE9 -> 0 | AH9: =AF9+Q9+N9 -> 0 | AI9: =AG9+S9+P9 -> 0 | AL9: =AI9-M9 -> 0
J10: =H10*I10 -> 0 | M10: =K10*L10 -> 0 | P10: =N10*O10 -> 0 | S10: =Q10*R10 -> 0 | V10: =T10*U10 -> 0 | Y10: =W10*X10 -> 0 | AB10: =Z10*AA10 -> 0 | AE10: =AC10*AD10 -> 0 | AF10: =T10+W10+Z10+AC10 -> 0 | AG10: =V10+Y10+AB10+AE10 -> 0 | AH10: =AF10+Q10+N10 -> 0 | AI10: =AG10+S10+P10 -> 0 | AL10: =AI10-M10 -> 0
J11: =H11*I11 -> 0 | M11: =K11*L11 -> 0 | P11: =N11*O11 -> 0 | S11: =Q11*R11 -> 0 | V11: =T11*U11 -> 0 | Y11: =W11*X11 -> 0 | AB11: =Z11*AA11 -> 0 | AE11: =AC11*AD11 -> 0 | AF11: =T11+W11+Z11+AC11 -> 0 | AG11: =V11+Y11+AB11+AE11 -> 0 | AH11: =AF11+Q11+N11 -> 0 | AI11: =AG11+S11+P11 -> 0 | AL11: =AI11-M11 -> 0
J12: =H12*I12 -> 0 | M12: =K12*L12 -> 0 | P12: =N12*O12 -> 0 | S12: =Q12*R12 -> 0 | V12: =T12*U12 -> 0 | Y12: =W12*X12 -> 0 | AB12: =Z12*AA12 -> 0 | AE12: =AC12*AD12 -> 0 | AF12: =T12+W12+Z12+AC12 -> 0 | AG12: =V12+Y12+AB12+AE12 -> 0 | AH12: =AF12+Q12+N12 -> 0 | AI12: =AG12+S12+P12 -> 0 | AL12: =AI12-M12 -> 0
J13: =H13*I13 -> 0 | M13: =K13*L13 -> 0 | P13: =N13*O13 -> 0 | S13: =Q13*R13 -> 0 | V13: =T13*U13 -> 0 | Y13: =W13*X13 -> 0 | AB13: =Z13*AA13 -> 0 | AE13: =AC13*AD13 -> 0 | AF13: =T13+W13+Z13+AC13 -> 0 | AG13: =V13+Y13+AB13+AE13 -> 0 | AH13: =AF13+Q13+N13 -> 0 | AI13: =AG13+S13+P13 -> 0 | AL13: =AI13-M13 -> 0
J14: =H14*I14 -> 0 | M14: =K14*L14 -> 0 | P14: =N14*O14 -> 0 | S14: =Q14*R14 -> 0 | V14: =T14*U14 -> 0 | Y14: =W14*X14 -> 0 | AB14: =Z14*AA14 -> 0 | AE14: =AC14*AD14 -> 0 | AF14: =T14+W14+Z14+AC14 -> 0 | AG14: =V14+Y14+AB14+AE14 -> 0 | AH14: =AF14+Q14+N14 -> 0 | AI14: =AG14+S14+P14 -> 0 | AL14: =AI14-M14 -> 0
J15: =H15*I15 -> 0 | M15: =K15*L15 -> 0 | P15: =N15*O15 -> 0 | S15: =Q15*R15 -> 0 | V15: =T15*U15 -> 0 | Y15: =W15*X15 -> 0 | AB15: =Z15*AA15 -> 0 | AE15: =AC15*AD15 -> 0 | AF15: =T15+W15+Z15+AC15 -> 0 | AG15: =V15+Y15+AB15+AE15 -> 0 | AH15: =AF15+Q15+N15 -> 0 | AI15: =AG15+S15+P15 -> 0 | AL15: =AI15-M15 -> 0
J16: =H16*I16 -> 0 | M16: =K16*L16 -> 0 | P16: =N16*O16 -> 0 | S16: =Q16*R16 -> 0 | V16: =T16*U16 -> 0 | Y16: =W16*X16 -> 0 | AB16: =Z16*AA16 -> 0 | AE16: =AC16*AD16 -> 0 | AF16: =T16+W16+Z16+AC16 -> 0 | AG16: =V16+Y16+AB16+AE16 -> 0 | AH16: =AF16+Q16+N16 -> 0 | AI16: =AG16+S16+P16 -> 0 | AL16: =AI16-M16 -> 0
J17: =H17*I17 -> 0 | M17: =K17*L17 -> 0 | P17: =N17*O17 -> 0 | S17: =Q17*R17 -> 0 | V17: =T17*U17 -> 0 | Y17: =W17*X17 -> 0 | AB17: =Z17*AA17 -> 0 | AE17: =AC17*AD17 -> 0 | AF17: =T17+W17+Z17+AC17 -> 0 | AG17: =V17+Y17+AB17+AE17 -> 0 | AH17: =AF17+Q17+N17 -> 0 | AI17: =AG17+S17+P17 -> 0 | AL17: =AI17-M17 -> 0
J18: =H18*I18 -> 0 | M18: =K18*L18 -> 0 | P18: =N18*O18 -> 0 | S18: =Q18*R18 -> 0 | V18: =T18*U18 -> 0 | Y18: =W18*X18 -> 0 | AB18: =Z18*AA18 -> 0 | AE18: =AC18*AD18 -> 0 | AF18: =T18+W18+Z18+AC18 -> 0 | AG18: =V18+Y18+AB18+AE18 -> 0 | AH18: =AF18+Q18+N18 -> 0 | AI18: =AG18+S18+P18 -> 0 | AL18: =AI18-M18 -> 0
J19: =H19*I19 -> 0 | M19: =K19*L19 -> 0 | P19: =N19*O19 -> 0 | S19: =Q19*R19 -> 0 | V19: =T19*U19 -> 0 | Y19: =W19*X19 -> 0 | AB19: =Z19*AA19 -> 0 | AE19: =AC19*AD19 -> 0 | AF19: =T19+W19+Z19+AC19 -> 0 | AG19: =V19+Y19+AB19+AE19 -> 0 | AH19: =AF19+Q19+N19 -> 0 | AI19: =AG19+S19+P19 -> 0 | AL19: =AI19-M19 -> 0
J20: =H20*I20 -> 0 | M20: =K20*L20 -> 0 | P20: =N20*O20 -> 0 | S20: =Q20*R20 -> 0 | V20: =T20*U20 -> 0 | Y20: =W20*X20 -> 0 | AB20: =Z20*AA20 -> 0 | AE20: =AC20*AD20 -> 0 | AF20: =T20+W20+Z20+AC20 -> 0 | AG20: =V20+Y20+AB20+AE20 -> 0 | AH20: =AF20+Q20+N20 -> 0 | AI20: =AG20+S20+P20 -> 0 | AL20: =AI20-M20 -> 0
... J25: =H25*I25 -> 0 | M25: =K25*L25 -> 0 | P25: =N25*O25 -> 0 | S25: =Q25*R25 -> 0 | V25: =T25*U25 -> 0 | Y25: =W25*X25 -> 0 | AB25: =Z25*AA25 -> 0 | AE25: =AC25*AD25 -> 0 | AF25: =T25+W25+Z25+AC25 -> 0 | AG25: =V25+Y25+AB25+AE25 -> 0 | AH25: =AF25+Q25+N25 -> 0 | AI25: =AG25+S25+P25 -> 0 | AL25: =AI25-M25 -> 0
D26: 합 계 | J26: =SUM(J8:J25) -> 0 | M26: =SUM(M8:M25) -> 0 | P26: =SUM(P8:P25) -> 0 | S26: =SUM(S8:S25) -> 0 | V26: =SUM(V8:V25) -> 0 | Y26: =SUM(Y8:Y25) -> 0 | AB26: =SUM(AB8:AB25) -> 0 | AE26: =SUM(AE8:AE25) -> 0 | AG26: =SUM(AG8:AG25) -> 0 | AI26: =SUM(AI8:AI25) -> 0 | AL26: =AI26-M26 -> 0
D28: GS네오텍 | G28: Page : | AJ28: GP-4050-07(1)

Sheet 5-2. 회선비산출내역
O1: 3
D2: [ ■ 본사 □ 현지 ] 재료비 산출내역
D3: 회선비 산출내역(1=Cloud 사용료(AWS/구글 등), 2=라이선스(국산/외산))
D4: ='0. 집행계획(갑지)'!D7 -> 1.공 사 명 : (공사코드: ) | AJ4: 【단위 : 원】
D5: 자재 코드 | E5: 품 명 | F5: 규 격 | G5: 단위 | H5: 계 약 | K5: 집행계획(A) | N5: 정산누계(B) [~25년] | Q5: 당기계획(C) [26년] | T5: 당기 이후 | AH5: 계(E=B+C+D) | AJ5: 비 고
T6: [27년] | W6: [28년] | Z6: [29년] | AC6: [30년] | AF6: 소계(D)
H7: 수량 | I7: 단가 | J7: 금액 | K7: 수량 | L7: 단가 | M7: 금액 | N7: 수량 | O7: 단가 | P7: 금액 | Q7: 수량 | R7: 단가 | S7: 금액 | T7: 수량 | U7: 단가 | V7: 금액 | W7: 수량 | X7: 단가 | Y7: 금액 | Z7: 수량 | AA7: 단가 | AB7: 금액 | AC7: 수량 | AD7: 단가 | AE7: 금액 | AF7: 수량 | AG7: 금액 | AH7: 수량 | AI7: 금액
J8: =H8*I8 -> 0 | M8: =K8*L8 -> 0 | P8: =N8*O8 -> 0 | S8: =Q8*R8 -> 0 | V8: =T8*U8 -> 0 | Y8: =W8*X8 -> 0 | AB8: =Z8*AA8 -> 0 | AE8: =AC8*AD8 -> 0 | AF8: =T8+W8+Z8+AC8 -> 0 | AG8: =V8+Y8+AB8+AE8 -> 0 | AH8: =AF8+Q8+N8 -> 0 | AI8: =AG8+S8+P8 -> 0
J9: =H9*I9 -> 0 | M9: =K9*L9 -> 0 | P9: =N9*O9 -> 0 | S9: =Q9*R9 -> 0 | V9: =T9*U9 -> 0 | Y9: =W9*X9 -> 0 | AB9: =Z9*AA9 -> 0 | AE9: =AC9*AD9 -> 0 | AF9: =T9+W9+Z9+AC9 -> 0 | AG9: =V9+Y9+AB9+AE9 -> 0 | AH9: =AF9+Q9+N9 -> 0 | AI9: =AG9+S9+P9 -> 0 | AL9: =AI9-M9 -> 0
J10: =H10*I10 -> 0 | M10: =K10*L10 -> 0 | P10: =N10*O10 -> 0 | S10: =Q10*R10 -> 0 | V10: =T10*U10 -> 0 | Y10: =W10*X10 -> 0 | AB10: =Z10*AA10 -> 0 | AE10: =AC10*AD10 -> 0 | AF10: =T10+W10+Z10+AC10 -> 0 | AG10: =V10+Y10+AB10+AE10 -> 0 | AH10: =AF10+Q10+N10 -> 0 | AI10: =AG10+S10+P10 -> 0 | AL10: =AI10-M10 -> 0
